Workbook

Sheet Labor
A1: index | B1: KEY | C1: Drawing Number | D1: Component | E1: Description | F1: Reducing | G1: Material | H1: Merged_Props | I1: connection_qty | J1: pressure_rating | K1: class_rating | L1: Thickness | M1: weight_class | N1: length | O1: connection_type | P1: Size1 | Q1: Size2 | R1: Size3 | S1: Size4 | T1: Size5 | U1: Size6 | V1: Size7 | W1: Budget | X1: Quantity | Y1: BudgXQty | Z1: Tig | AA1: Argon | AB1: Subtotal | AC1: Xray | AD1: HvyEqp | AE1: Env | AF1: ClnRoom | AG1: Cond | AH1: Grade | AI1: OT | AJ1: Total | AK1: CommodityCode | AL1: ShopField | AM1: UOM | AN1: BuildingNo | AO1: ConnectionSize | AP1: CWPNo | AQ1: Elastomer | AR1: Hygienic | AS1: Impact | AT1: Index | AU1: InsulationCode | AV1: IsometricDrawingNumber | AW1: LineNumber | AX1: ModuleNo | AY1: Node | AZ1: PipeSchedule | BA1: ReferencePIDNumber | BB1: Rev | BC1: ServiceCode | BD1: TracingType
A2: 1 | B2: FLG|SS|WN|150|10|BU,BW|0.5|0.5 | C2: LP150-APL(100)-011015-01 | D2: FLG | E2: 0.5 IN WN SCH 10 150# FLG | G2: SS | H2: WN | I2: 2 | K2: 150 | L2: 10 | O2: BU,BW | P2: 0.5 | Q2: 0.5 | W2: 0.05 | X2: 1 | Y2: =X2*W2 -> 0.05 | Z2: =IF(AND(G2="SS",D2="BW"),_xlfn.XLOOKUP(P2,Multipliers!$A$2:$A$14,Multipliers!$B$2:$B$14),0) -> 0 | AA2: =IF(AND(G2="SS",D2="BW"),_xlfn.XLOOKUP(P2,Multipliers!$A$2:$A$14,Multipliers!$C$2:$C$14),0) -> 0 | AB2: =Y2+(Z2*X2)+(AA2*X2) -> 0.05 | AC2: =IF(D2="FS",0,Multipliers!$B$21*AB2) -> 0.0235 | AD2: =IF(D2="FS",0,IF(P2>=8,Multipliers!$B$22*AB2,0)) -> 0 | AE2: =IF(D2="FS",0,Multipliers!$B$23*AB2) -> 0.0025 | AF2: =IF(D2="FS",0,Multipliers!$B$24*AB2) -> 0 | AG2: =IF(D2="FS",1,Multipliers!$B$25) -> 1.3 | AH2: =IF(D2="FS",1,Multipliers!$B$26) -> 1.03 | AI2: =IF(D2="FS",1,Multipliers!$B$27) -> 1.14 | AJ2: =IF(AL2=2,(AB2+AC2+AD2+AF2+AE2)*AG2*AH2*AI2,(AB2+AC2+AD2+AF2+AE2)) -> 0.11601096 | AK2: 5PU3 | AL2: 2 | AM2: EA | AN2: Y | AP2: TFS00D005YSPP | AQ2: NE | AR2: NO | AS2: NO | AU2: 108 | AV2: LP1Y-PWP-101706-09 | AW2: LP1Y 6" DUP PWP (344) (108) 101706 | AX2: N/A | AY2: TFS | AZ2: 344 | BA2: LP1Y-DI-20000101 | BB2: 2 | BC2: PWP | BD2: ET

Sheet Sheet1
A1: LP1Y-PWP-014007-03
A2: LP1Y-SWP-014001-05
A3: LP1Y-WV-061046-27
A4: LP1Y-WV-061046-28

Sheet PieCharts
B1: MCAA | C1: Qty | D1: Field MHs | H1: SUMMIT | I1: Qty | J1: Field MHs
B2: Connections | C2: {=SUMPRODUCT(((Labor!D2:D2="BW")+(Labor!D2:D2="SW")+(Labor!D2:D2="OLW")+(Labor!D2:D2="BU")+(Labor!D2:D2="THRD"))*(Labor!AL2:AL2=2)*Labor!X2:X2)} -> 0 | D2: {=SUMPRODUCT(((Labor!D2:D2="BW")+(Labor!D2:D2="SW")+(Labor!D2:D2="OLW")+(Labor!D2:D2="BU")+(Labor!D2:D2="THRD"))*(Labor!AL2:AL2=2)*Labor!AJ2:AJ2)} -> 0 | H2: Connections | I2: {=SUMPRODUCT(((Labor!D2:D2="BW")+(Labor!D2:D2="SW")+(Labor!D2:D2="OLW")+(Labor!D2:D2="BU")+(Labor!D2:D2="THRD"))*(Labor!AL2:AL2=2)*Labor!X2:X2)} -> 0 | J2: {=SUMPRODUCT(((Labor!D2:D2="BW")+(Labor!D2:D2="SW")+(Labor!D2:D2="OLW")+(Labor!D2:D2="BU")+(Labor!D2:D2="THRD"))*(Labor!AL2:AL2=2)*Labor!#REF!)} -> #REF!
B3: Handling + Prep | D3: {=SUMPRODUCT((Labor!D2:D2<>"BW")*(Labor!D2:D2<>"SW")*(Labor!D2:D2<>"OLW")*(Labor!D2:D2<>"BU")*(Labor!D2:D2<>"THRD")*(Labor!D2:D2<>"")*(Labor!AL2:AL2=2)*Labor!AJ2:AJ2)} -> 0.11601096 | H3: Handling + Prep | J3: {=SUMPRODUCT((Labor!D2:D2<>"BW")*(Labor!D2:D2<>"SW")*(Labor!D2:D2<>"OLW")*(Labor!D2:D2<>"BU")*(Labor!D2:D2<>"THRD")*(Labor!D2:D2<>"")*(Labor!AL2:AL2=2)*Labor!#REF!)} -> #REF!
B4: Total | D4: =SUM(D2:D3) -> 0.11601096 | H4: Total | J4: =SUM(J2:J3) -> #REF!
A25: SHOP WELDS
A26: Rate | B26: Qty | D26: Mhs
A27: MCAA | B27: {=SUMPRODUCT(((Labor!D2:D2="BW")+(Labor!D2:D2="SW")+(Labor!D2:D2="OLW")+(Labor!D2:D2="BU")+(Labor!D2:D2="THRD"))*(Labor!AL2:AL2=1)*Labor!X2:X2)} -> 0 | D27: {=SUMPRODUCT(((Labor!D2:D2="BW")+(Labor!D2:D2="SW"))*(Labor!AL2:AL2=1)*Labor!AJ2:AJ2)} -> 0
A28: SUMMIT | B28: {=SUMPRODUCT(((Labor!D2:D2="BW")+(Labor!D2:D2="SW")+(Labor!D2:D2="OLW")+(Labor!D2:D2="BU")+(Labor!D2:D2="THRD"))*(Labor!AL2:AL2=1)*Labor!X2:X2)} -> 0 | D28: {=SUMPRODUCT(((Labor!D2:D2="BW")+(Labor!D2:D2="SW"))*(Labor!AL2:AL2=1)*Labor!#REF!)} -> #REF!
A29: Total | B29: =SUM(B27:B28) -> 0 | D29: =SUM(D27:D28) -> #REF!

Sheet Summary
A1: TAKEOFF SUMMARY
A2: Total Drawings | B2: 2021
A3: Total BOM Items | B3: 32142
A4: Total Connections | B4: 32021
A5: Total MHs | B5: 201739.35
A6: Shop Items | B6: 14058
A7: Field Items | B7: 18084
A8: Flagged Items | B8: 637
A9: Low Confidence | B9: 100
A10: Medium Confidence | B10: 537
A11: Malformed Sizes | B11: 0
A13: COMPONENTS BY TYPE | B13: Count
A14: 45L | B14: 265
A15: 90L | B15: 2042
A16: ADPT | B16: 1
A17: ANLZR | B17: 27
A18: BOLT | B18: 3028
A19: CAP | B19: 39
A20: COV | B20: 42
A21: CPLG | B21: 370
A22: DPAN | B22: 1
A23: EWSH | B23: 5
A24: F8B | B24: 1
A25: FLG | B25: 714
... A71: WOL | B71: 16
A73: CONNECTIONS BY TYPE | B73: Count | C73: MHs
A74: BU | B74: 4892 | C74: 5271.89
A75: BW | B75: 21374 | C75: 55263.366
A76: SCRD | B76: 1236 | C76: 441.535
A77: SW | B77: 4519 | C77: 4890.931
A79: CONNECTIONS BY SIZE | B79: Count | C79: MHs
A80: 0.25 | B80: 31 | C80: 9.34
A81: 0.375 | B81: 134 | C81: 33.86
A82: 0.5 | B82: 467 | C82: 462.367
A83: 0.75 | B83: 5018 | C83: 5282.585
A84: 1 | B84: 4982 | C84: 8082.353
A85: 1.25 | B85: 478 | C85: 500.468
A86: 1.5 | B86: 853 | C86: 1689.45
A87: 2 | B87: 13321 | C87: 30090.884
A88: 3 | B88: 3421 | C88: 9006.324
...

Sheet Multipliers
A1: SIZE | B1: TIG ROOT | C1: INERT GAS
A2: 0.5 | B2: 0.21 | C2: 0.21
A3: 0.75 | B3: 0.23 | C3: 0.21
A4: 1.25 | B4: 0.26 | C4: 0.21
A5: 1.5 | B5: 0.3 | C5: 0.21
A6: 1 | B6: 0.42 | C6: 0.21
A7: 2 | B7: 0.84 | C7: 0.66
A8: 3 | B8: 1 | C8: 0.95
A9: 4 | B9: 1.36 | C9: 1.31
A10: 6 | B10: 1.73 | C10: 1.74
A11: 12 | B11: 3.4 | C11: 2.45
A12: 8 | B12: 2.19 | C12: 1.98
A13: 10 | B13: 2.77 | C13: 2.67
A14: 14 | B14: 3.97 | C14: 2.67
A20: MULTIPLIERS
A21: XRAY | B21: 0.47
A22: HEAVY EQUIP (SIZE > 8IN) | B22: 0.8
A23: ENVIRONMENTAL | B23: 0.05
A24: CLEAN ROOM | B24: 0
A25: SITE CONDITIONS | B25: 1.3
A26: GRADE (79% X 1.3) | B26: 1.03
A27: OVERTIME | B27: 1.14

Sheet worksheet
A1: items keys | B1: mcaa abbr | C1: desc | D1: NOTES
A2: 45L | B2: EL45 | C2: ELL 45 DEG 3000# SW STL A105 - 5478106 | D2: NEED CLASS FOR ALL SW
A3: 90L | B3: EL90 | C3: ELL 90 DEG 316 SS COMP ENDS - 5509403 | D3: NEED CLASS FOR ALL SW
A4: ADPT | B4: ADPT | C4: ADAPTER TC X 10S 316L SS - 5546514
A5: ANLZR | B5: FE | C5: AE - ANALYZER, ELEMENT, PH, NON-HYG - LP1YAE1010AC | D5: 4.9 MHS. USED FLOW TRANSMITTER FROM INSTUMENTATION
A6: BOLT | B6: NOT IN MCAA | C6: STUD-BOLT A193 GR B7 W/A194 GR 2H NUTS W/ STAR WASHERS - 3.25 in. Length - 5675648L1
A7: BU | B7: BU | C7: 8 IN - 40 - 150 - CS - BU - One Flange
A8: BW | B8: BW | C8: 8 IN - 40 - CS - BW
A9: CAP | B9: CAP | C9: CAP SCH 10S 316/316L SS A403 - 5448862
A10: COV | B10: COV | C10: PIPE COVER PVC PE - LP1Y PC-1114V2
A11: CPLG | B11: CPL | C11: MALE CONNECTOR 316 SS COMP X MNPT - 5509913
A12: DPAN | B12: DPAN | C12: DRIP PAN HASTELLOY FOR EQUIPMENT - LP1Y DP-1761A
A13: EWSH | B13: SiteSpecific | C13: SAFETY SHOWER AND EYEWASH COMBINATION - LP1Y SSEW-00-1015-01
A14: F8B | B14: FLG | C14: FIGURE 8 BLANK 150# RF 316/316L SS - 5749749 | D14: MAKE FIGURE 8 A BLIND body type in the app and takeoff
A15: FLG | B15: FLG | C15: FLG SW 150# RF 316/316L SS 10S BORE - 5608148
A16: FLGLJ | B16: FLG | C16: FLG LAP JOINT 150# 316 SS
A17: FLGB | B17: FLG | C17: FLG BLIND 150# RF 316/316L SS
A18: FLGA | B18: FLGA | C18: FLG ADAPTER 150# RF/FF X GRV DI GRADE P GASKET NSF - 5484771L0 | F18: 43526
A19: FLGR | B19: FLG | C19: FLG WN REDUCING 150# RF 316/316L SS 10S BORE - LP1Y RF-3021R1 | F19: newComp
A20: FO | B20: FMO | C20: 150 PSI Flow Meter Wafer Type, Orifice
A21: FS | B21: FS | C21: PIPE SUPPORT | D21: USE 6 MHS
A22: GAUGE | B22: GAUGE4ROD | C22: PI - PRESSURE, GAUGE, LOCAL, DIRECT, N-HYG, SEAL - LP1YPI0970AB | D22: 1.05 mhS (NOT SCRAPED: INSTRUMENTATION
A23: GGLASS | B23: SiteSpecific | C23: SIGHT GLASS BULLSEYE 150# HASTELLOY RF - LP1Y SG-1761A1
A24: GRV | B24: GRV | C24: 2 IN - 40 - CS - GRV
A25: GSKT | B25: NOT IN MCAA | C25: GASKET 150# PTFE RING 1/8" THK LOW STRESS - 5669399L
A26: HEAT | B26: HEAT | C26: WATER HEATER 316 SS MNPT - LP1Y WH-1940F
A27: HOSE | B27: ADPT | C27: HOSE CONNECTION HASTELLOY BW ADAPTER CAMLOCK WITH DUST CAP - LP1Y CCU-1783N1
A28: INST | B28: FE | C28: FE - FLOW, ELEMENT, CORIOLIS, NON-HYG - LP1YFE1621A | D28: 4.9 MHS. USED FLOW TRANSMITTER FROM INSTUMENTATION
A29: LOL | B29: LOL | C29: LATROLET 3000# SW 316/316L SS - 5529072
A30: METER | B30: FE | C30: FE - FLOW, ELEMENT, CORIOLIS, NON-HYG - LP1YFE1080G | D30: 4.9 MHS. USED FLOW TRANSMITTER FROM INSTUMENTATION
A31: NIP | B31: NIP | C31: NIPPLE SCH 80S 316/316L SS TBE 3" LONG - 5540551
A32: OLW | B32: BW | C32: 0.5 IN - 40 - 3000 - CS - OLW | D32: these now create a BW and whatever the olet includes on the other side (all olets follow this rule now)
A33: PIPE | B33: PIPE | C33: PIPE SCH 10S EFW DUPLEX STL S32205-W - Fab Pipe Handling | D33: ONLY USING ss AND cs BUTT WELD.
A34: PIPET | B34: PIPET | C34: PIPET 10S X 3000# SCRD 316/316L SS - 5515773
A35: PLG | B35: PLG | C35: PLUG ROUND HEAD SCRD STL A105 - 5490665
A36: RED | B36: REDCON, REDECC | C36: REDUCER CONC SCH 10S 316/316L SS A403-W - 5450717 | D36: ALL REDS MUST BE REDCON OR REDECC
A37: REDT | B37: TEERED | C37: TEE RED SCH 10S HASTELLOY C22 B366-W - 5469758L
A38: SAFSHW | B38: SiteSpecific | C38: SAFETY SHOWER AND EYEWASH COMBINATION - LP1Y SSEW-00-1003-01
A39: SCRD | B39: THRD | C39: 0.25 IN - 10S - 3000 - SS - SCRD
A40: SOL | B40: SOL | C40: SOCKOLET 3000# STL A105 - 5532671 | D40: these now create a BW and whatever the olet includes on the other side (all olets follow this rule now)
...

Sheet Rates
BO1: 0.47 | BQ1: 0.08 | BS1: 0.05 | BU1: 0.71 | BX1: 0.6 | BY1: 0.4 | BZ1: 0.9 | CA1: 1.3 | CB1: 1.2 | CC1: 1.17
G2: Handle Pipe | I2: Handle Fittings - L90 | L2: Handle Fittings - L45 | O2: Handle Fittings - OLET | R2: Handle Fittings - TEE | U2: Handle Fittings - REDUCER | X2: Handle VALVE | AA2: Handle FLANGE | AD2: Handle Fittings - STUB END | AG2: Handle Fittings - NIPPLE | AJ2: Handle Fittings - CAP | AM2: Handle Fittings - COUPLING | AP2: Handle Fittings - FLEX HOSE | AS2: PIPE SUPPORT | AV2: FLANGE BOLT-UP | AY2: Joint Prep - Cut & Bevel | BC2: Join Pipe | BF2: Join Fittings | BI2: SUB-TOTAL | BJ2: TIG Weld Factor | BL2: Inert Gas Purge | BO2: X-Ray Quality Weld | BQ2: Heavy Equipment | BS2: Environmental | BU2: Clean Room | CA2: Conditions | CB2: Grade | CC2: OVERTIME
D3: MCAA SECTION REFERENCE: | G3: Piping System Units | I3: Piping System Units | L3: Piping System Units | O3: Piping System Units | R3: Piping System Units | U3: Piping System Units | X3: Piping System Units | AA3: Piping System Units | AD3: Piping System Units | AG3: Piping System Units | AJ3: Piping System Units | AM3: Piping System Units | AP3: Piping System Units | AS3: Piping System Units | AV3: Piping System Units | AY3: Piping System Units | BC3: Piping System Units | BF3: Piping System Units | BJ3: Piping System Units | BL3: Miscellaneous Labor Operations | BO3: Labor Correction Factors Part VIII | BQ3: Labor Correction Factors Part VII | BS3: Labor Correction Factors Part IV | BU3: Clean Room Labor Correction Factors | BX3: Site Hours Split | BY3: OSM Hours Split | BZ3: OSM Factor | CA3: Labor Correction Factors Part V | CB3: Labor Correction Factors Part IV | CC3: Labor Correction Factors Part IV
A4: SYSTEM | B4: SPEC | C4: Size | D4: LF Pipe | E4: SERVICE | F4: COMMENTS | G4: MCAA Unit labor hour | H4: Labor Hour | I4: QTY | J4: MCAA Unit labor hour | K4: Labor Hour | L4: QTY | M4: MCAA Unit labor hour | N4: Labor Hour | O4: QTY | P4: MCAA Unit labor hour | Q4: Labor Hour | R4: QTY | S4: MCAA Unit labor hour | T4: Labor Hour | U4: QTY | V4: MCAA Unit labor hour | W4: Labor Hour | X4: QTY | Y4: MCAA Unit labor hour | Z4: Labor Hour | AA4: QTY | AB4: MCAA Unit labor hour | AC4: Labor Hour | AD4: QTY | AE4: MCAA Unit labor hour | AF4: Labor Hour | AG4: QTY | AH4: MCAA Unit labor hour | AI4: Labor Hour | AJ4: QTY | AK4: MCAA Unit labor hour | AL4: Labor Hour | AM4: QTY | AN4: MCAA Unit labor hour | AO4: Labor Hour | AP4: QTY | AQ4: MCAA Unit labor hour | AR4: Labor Hour | AS4: QTY | AT4: MCAA Unit labor hour | AU4: Labor Hour | AV4: QTY | AW4: MCAA Unit labor hour | AX4: Labor Hour | AY4: Qty | AZ4: MCAA Unit labor hour per Dia Inch | BA4: Unit Labor | BB4: Labor Hour | BC4: QTY | BD4: MCAA Unit labor hour | BE4: Labor Hour | BF4: QTY | BG4: MCAA Unit labor hour | BH4: Labor Hour | BJ4: MCAA Adjustment Factor | BK4: Labor Hour | BL4: MCAA Adjustment Factor | BM4: Labor Hour | BN4: Subtotal Hours | BO4: MCAA Adjustment Factor | BP4: Labor Hour | BQ4: MCAA Heavy Equipment Factor | BR4: Labor Hour | BS4: MCAA Environmental Factor | BT4: Labor Hour | BU4: MCC Clean Room Factor | BV4: Labor Hour | BW4: Subtotal | BX4: Site Hours | BY4: OSM Hours | BZ4: OSM Area Adjustment "Only applied to OSM Hours | CA4: Site Area Factor | CB4: MCAA Grade Level Adjustment | CC4: MCAA Grade Level Adjustment | CD4: Total Onsite Factored Hours | CE4: Total OSM Factored Hours | CF4: Total Factored Labor Hours
B5: ADA | C5: 2.5 | D5: 200 | F5: CS - WELD | G5: 0.13 | H5: =ROUNDUP(G5*D5,0) -> 26 | I5: 10 | J5: 0.09 | K5: =ROUNDUP(I5*J5,0) -> 1 | L5: 10 | M5: 0.07 | N5: =ROUNDUP(M5*L5,0) -> 1 | O5: 10 | P5: 0.08 | Q5: =ROUNDUP(P5*O5,0) -> 1 | R5: 10 | S5: 0.13 | T5: =ROUNDUP(S5*R5,0) -> 2 | U5: 10 | V5: 0.07 | W5: =ROUNDUP(V5*U5,0) -> 1 | X5: 10 | Y5: 0.38 | Z5: =ROUNDUP(Y5*X5,0) -> 4 | AA5: 10 | AB5: 0.18 | AC5: =ROUNDUP(AB5*AA5,0) -> 2 | AD5: 10 | AF5: =ROUNDUP(AE5*AD5,0) -> 0 | AI5: =ROUNDUP(AH5*AG5,0) -> 0 | AJ5: 2 | AK5: 0.06 | AL5: =ROUNDUP(AK5*AJ5,0) -> 1 | AO5: =ROUNDUP(AN5*AM5,0) -> 0 | AR5: =ROUNDUP(AQ5*AP5,0) -> 0 | AU5: =ROUNDUP(AT5*AS5,0) -> 0 | AV5: =AA5 -> 10 | AW5: 0.74 | AX5: =ROUNDUP(AW5*AV5,0) -> 8 | AY5: =BC5+BF5 -> 132 | AZ5: 0.345 | BA5: =AZ5*C5 -> 0.8625 | BB5: =ROUNDUP(BA5*AY5,0) -> 114 | BC5: =ROUNDUP(D5/20,0) -> 10 | BD5: 1.71 | BE5: =ROUNDUP(BC5*BD5,0) -> 18 | BF5: =(I5*2)+(L5*2)+(O5*1)+(R5*3)+(U5*2)+(AA5*1)+(AD5*1)+(AG5*2)+(AJ5*1)+(AM5*2)+(AP5*2)+(AS5*2) -> 122 | BG5: 1.71 | BH5: =ROUNDUP(BF5*BG5,0) -> 209 | BI5: =H5+K5+N5+Q5+T5+W5+Z5+AC5+AF5+AI5+AL5+AO5+AR5+AU5+AX5+BB5+BE5+BH5 -> 388 | BK5: =ROUNDUP((BC5+BF5)*BJ5,0) -> 0 | BM5: =ROUNDUP((BC5+BF5)*BL5,0) -> 0 | BN5: =ROUNDUP(H5+K5+N5+Q5+T5+W5+Z5+AC5+AF5+AI5+AL5+AO5+AR5+AU5+AX5+BB5+BE5+BH5+BK5+BM5,0) -> 388 | BO5: =$BO$1 -> 0.47 | BP5: =ROUNDUP(BN5*BO5,0) -> 183 | BR5: =ROUNDUP(BN5*BQ5,0) -> 0 | BS5: =$BS$1 -> 0.05 | BT5: =ROUNDUP(BN5*BS5,0) -> 20 | BV5: =BU5*BN5 -> 0 | BW5: =BN5+BP5+BR5+BT5 -> 591 | BX5: =BW5*$BX$1 -> 354.6 | BY5: =BW5*$BY$1 -> 236.4 | BZ5: =BY5*$BZ$1 -> 212.76 | CA5: =$CA$1 -> 1.3 | CB5: =$CB$1 -> 1.2 | CC5: =$CC$1 -> 1.17 | CD5: =CC5*CB5*CA5*BX5 -> 647.21592 | CE5: =BZ5 -> 212.76 | CF5: =BW5*CA5*CB5 -> 921.96
B6: ADA | C6: 3 | F6: CS - WELD | G6: 0.16 | H6: =ROUNDUP(G6*D6,0) -> 0 | J6: 0.12 | K6: =ROUNDUP(I6*J6,0) -> 0 | M6: 0.08 | N6: =ROUNDUP(M6*L6,0) -> 0 | P6: 0.11 | Q6: =ROUNDUP(P6*O6,0) -> 0 | S6: 0.17 | T6: =ROUNDUP(S6*R6,0) -> 0 | V6: 0.08 | W6: =ROUNDUP(V6*U6,0) -> 0 | Y6: 0.41 | Z6: =ROUNDUP(Y6*X6,0) -> 0 | AB6: 0.22 | AC6: =ROUNDUP(AB6*AA6,0) -> 0 | AF6: =ROUNDUP(AE6*AD6,0) -> 0 | AI6: =ROUNDUP(AH6*AG6,0) -> 0 | AK6: 0.07 | AL6: =ROUNDUP(AK6*AJ6,0) -> 0 | AO6: =ROUNDUP(AN6*AM6,0) -> 0 | AR6: =ROUNDUP(AQ6*AP6,0) -> 0 | AU6: =ROUNDUP(AT6*AS6,0) -> 0 | AV6: =AA6 -> 0 | AW6: 0.71 | AX6: =ROUNDUP(AW6*AV6,0) -> 0 | AY6: =BC6+BF6 -> 0 | AZ6: 0.345 | BA6: =AZ6*C6 -> 1.035 | BB6: =ROUNDUP(BA6*AY6,0) -> 0 | BC6: =ROUNDUP(D6/20,0) -> 0 | BD6: 1.79 | BE6: =ROUNDUP(BC6*BD6,0) -> 0 | BF6: =(I6*2)+(L6*2)+(O6*1)+(R6*3)+(U6*2)+(AA6*1)+(AD6*1)+(AG6*2)+(AJ6*1)+(AM6*2)+(AP6*2)+(AS6*2) -> 0 | BG6: 1.79 | BH6: =ROUNDUP(BF6*BG6,0) -> 0 | BI6: =H6+K6+N6+Q6+T6+W6+Z6+AC6+AF6+AI6+AL6+AO6+AR6+AU6+AX6+BB6+BE6+BH6 -> 0 | BK6: =ROUNDUP((BC6+BF6)*BJ6,0) -> 0 | BM6: =ROUNDUP((BC6+BF6)*BL6,0) -> 0 | BN6: =ROUNDUP(H6+K6+N6+Q6+T6+W6+Z6+AC6+AF6+AI6+AL6+AO6+AR6+AU6+AX6+BB6+BE6+BH6+BK6+BM6,0) -> 0 | BO6: =$BO$1 -> 0.47 | BP6: =ROUNDUP(BN6*BO6,0) -> 0 | BR6: =ROUNDUP(BN6*BQ6,0) -> 0 | BS6: =$BS$1 -> 0.05 | BT6: =ROUNDUP(BP6*BS6,0) -> 0 | BV6: =BU6*BN6 -> 0 | BW6: =BN6+BR6 -> 0 | BX6: =BW6*$BX$1 -> 0 | BY6: =BW6*$BY$1 -> 0 | BZ6: =BY6*$BZ$1 -> 0 | CA6: =$CA$1 -> 1.3 | CB6: =$CB$1 -> 1.2 | CC6: =$CC$1 -> 1.17 | CD6: =CC6*CB6*CA6*BX6 -> 0 | CE6: =BZ6 -> 0 | CF6: =BW6*CA6*CB6 -> 0
B7: ADA | C7: 4 | F7: CS - WELD | G7: 0.21 | H7: =ROUNDUP(G7*D7,0) -> 0 | J7: 0.18 | K7: =ROUNDUP(I7*J7,0) -> 0 | M7: 0.11 | N7: =ROUNDUP(M7*L7,0) -> 0 | P7: 0.14 | Q7: =ROUNDUP(P7*O7,0) -> 0 | S7: 0.24 | T7: =ROUNDUP(S7*R7,0) -> 0 | V7: 0.1 | W7: =ROUNDUP(V7*U7,0) -> 0 | Y7: 0.55 | Z7: =ROUNDUP(Y7*X7,0) -> 0 | AB7: 0.29 | AC7: =ROUNDUP(AB7*AA7,0) -> 0 | AF7: =ROUNDUP(AE7*AD7,0) -> 0 | AI7: =ROUNDUP(AH7*AG7,0) -> 0 | AK7: 0.08 | AL7: =ROUNDUP(AK7*AJ7,0) -> 0 | AO7: =ROUNDUP(AN7*AM7,0) -> 0 | AR7: =ROUNDUP(AQ7*AP7,0) -> 0 | AU7: =ROUNDUP(AT7*AS7,0) -> 0 | AV7: =AA7 -> 0 | AW7: 1.49 | AX7: =ROUNDUP(AW7*AV7,0) -> 0 | AY7: =BC7+BF7 -> 0 | AZ7: 0.345 | BA7: =AZ7*C7 -> 1.38 | BB7: =ROUNDUP(BA7*AY7,0) -> 0 | BC7: =ROUNDUP(D7/20,0) -> 0 | BD7: 2.21 | BE7: =ROUNDUP(BC7*BD7,0) -> 0 | BF7: =(I7*2)+(L7*2)+(O7*1)+(R7*3)+(U7*2)+(AA7*1)+(AD7*1)+(AG7*2)+(AJ7*1)+(AM7*2)+(AP7*2)+(AS7*2) -> 0 | BG7: 2.21 | BH7: =ROUNDUP(BF7*BG7,0) -> 0 | BI7: =H7+K7+N7+Q7+T7+W7+Z7+AC7+AF7+AI7+AL7+AO7+AR7+AU7+AX7+BB7+BE7+BH7 -> 0 | BK7: =ROUNDUP((BC7+BF7)*BJ7,0) -> 0 | BM7: =ROUNDUP((BC7+BF7)*BL7,0) -> 0 | BN7: =ROUNDUP(H7+K7+N7+Q7+T7+W7+Z7+AC7+AF7+AI7+AL7+AO7+AR7+AU7+AX7+BB7+BE7+BH7+BK7+BM7,0) -> 0 | BO7: =$BO$1 -> 0.47 | BP7: =ROUNDUP(BN7*BO7,0) -> 0 | BR7: =ROUNDUP(BN7*BQ7,0) -> 0 | BS7: =$BS$1 -> 0.05 | BT7: =ROUNDUP(BP7*BS7,0) -> 0 | BV7: =BU7*BN7 -> 0 | BW7: =BN7+BR7 -> 0 | BX7: =BW7*$BX$1 -> 0 | BY7: =BW7*$BY$1 -> 0 | BZ7: =BY7*$BZ$1 -> 0 | CA7: =$CA$1 -> 1.3 | CB7: =$CB$1 -> 1.2 | CC7: =$CC$1 -> 1.17 | CD7: =CC7*CB7*CA7*BX7 -> 0 | CE7: =BZ7 -> 0 | CF7: =BW7*CA7*CB7 -> 0
B8: ADA | C8: 6 | F8: CS - WELD | G8: 0.28 | H8: =ROUNDUP(G8*D8,0) -> 0 | J8: 0.41 | K8: =ROUNDUP(I8*J8,0) -> 0 | M8: 0.23 | N8: =ROUNDUP(M8*L8,0) -> 0 | P8: 0.23 | Q8: =ROUNDUP(P8*O8,0) -> 0 | S8: 0.59 | T8: =ROUNDUP(S8*R8,0) -> 0 | V8: 0.18 | W8: =ROUNDUP(V8*U8,0) -> 0 | Y8: 0.8 | Z8: =ROUNDUP(Y8*X8,0) -> 0 | AB8: 0.44 | AC8: =ROUNDUP(AB8*AA8,0) -> 0 | AF8: =ROUNDUP(AE8*AD8,0) -> 0 | AI8: =ROUNDUP(AH8*AG8,0) -> 0 | AK8: 0.14 | AL8: =ROUNDUP(AK8*AJ8,0) -> 0 | AO8: =ROUNDUP(AN8*AM8,0) -> 0 | AR8: =ROUNDUP(AQ8*AP8,0) -> 0 | AU8: =ROUNDUP(AT8*AS8,0) -> 0 | AV8: =AA8 -> 0 | AW8: 1.63 | AX8: =ROUNDUP(AW8*AV8,0) -> 0 | AY8: =BC8+BF8 -> 0 | AZ8: 0.345 | BA8: =AZ8*C8 -> 2.07 | BB8: =ROUNDUP(BA8*AY8,0) -> 0 | BC8: =ROUNDUP(D8/20,0) -> 0 | BD8: 2.8 | BE8: =ROUNDUP(BC8*BD8,0) -> 0 | BF8: =(I8*2)+(L8*2)+(O8*1)+(R8*3)+(U8*2)+(AA8*1)+(AD8*1)+(AG8*2)+(AJ8*1)+(AM8*2)+(AP8*2)+(AS8*2) -> 0 | BG8: 2.8 | BH8: =ROUNDUP(BF8*BG8,0) -> 0 | BI8: =H8+K8+N8+Q8+T8+W8+Z8+AC8+AF8+AI8+AL8+AO8+AR8+AU8+AX8+BB8+BE8+BH8 -> 0 | BK8: =ROUNDUP((BC8+BF8)*BJ8,0) -> 0 | BM8: =ROUNDUP((BC8+BF8)*BL8,0) -> 0 | BN8: =ROUNDUP(H8+K8+N8+Q8+T8+W8+Z8+AC8+AF8+AI8+AL8+AO8+AR8+AU8+AX8+BB8+BE8+BH8+BK8+BM8,0) -> 0 | BO8: =$BO$1 -> 0.47 | BP8: =ROUNDUP(BN8*BO8,0) -> 0 | BR8: =ROUNDUP(BN8*BQ8,0) -> 0 | BS8: =$BS$1 -> 0.05 | BT8: =ROUNDUP(BP8*BS8,0) -> 0 | BV8: =BU8*BN8 -> 0 | BW8: =BN8+BR8 -> 0 | BX8: =BW8*$BX$1 -> 0 | BY8: =BW8*$BY$1 -> 0 | BZ8: =BY8*$BZ$1 -> 0 | CA8: =$CA$1 -> 1.3 | CB8: =$CB$1 -> 1.2 | CC8: =$CC$1 -> 1.17 | CD8: =CC8*CB8*CA8*BX8 -> 0 | CE8: =BZ8 -> 0 | CF8: =BW8*CA8*CB8 -> 0
B9: ADA | C9: 8 | F9: CS - WELD | G9: 0.34 | H9: =ROUNDUP(G9*D9,0) -> 0 | J9: 0.77 | K9: =ROUNDUP(I9*J9,0) -> 0 | M9: 0.41 | N9: =ROUNDUP(M9*L9,0) -> 0 | P9: 0.39 | Q9: =ROUNDUP(P9*O9,0) -> 0 | S9: 0.96 | T9: =ROUNDUP(S9*R9,0) -> 0 | V9: 0.26 | W9: =ROUNDUP(V9*U9,0) -> 0 | Y9: 1.19 | Z9: =ROUNDUP(Y9*X9,0) -> 0 | AB9: 0.72 | AC9: =ROUNDUP(AB9*AA9,0) -> 0 | AF9: =ROUNDUP(AE9*AD9,0) -> 0 | AI9: =ROUNDUP(AH9*AG9,0) -> 0 | AK9: 0.21 | AL9: =ROUNDUP(AK9*AJ9,0) -> 0 | AO9: =ROUNDUP(AN9*AM9,0) -> 0 | AR9: =ROUNDUP(AQ9*AP9,0) -> 0 | AU9: =ROUNDUP(AT9*AS9,0) -> 0 | AV9: =AA9 -> 0 | AW9: 1.58 | AX9: =ROUNDUP(AW9*AV9,0) -> 0 | AY9: =BC9+BF9 -> 0 | AZ9: 0.345 | BA9: =AZ9*C9 -> 2.76 | BB9: =ROUNDUP(BA9*AY9,0) -> 0 | BC9: =ROUNDUP(D9/20,0) -> 0 | BD9: 3.5 | BE9: =ROUNDUP(BC9*BD9,0) -> 0 | BF9: =(I9*2)+(L9*2)+(O9*1)+(R9*3)+(U9*2)+(AA9*1)+(AD9*1)+(AG9*2)+(AJ9*1)+(AM9*2)+(AP9*2)+(AS9*2) -> 0 | BG9: 3.5 | BH9: =ROUNDUP(BF9*BG9,0) -> 0 | BI9: =H9+K9+N9+Q9+T9+W9+Z9+AC9+AF9+AI9+AL9+AO9+AR9+AU9+AX9+BB9+BE9+BH9 -> 0 | BK9: =ROUNDUP((BC9+BF9)*BJ9,0) -> 0 | BM9: =ROUNDUP((BC9+BF9)*BL9,0) -> 0 | BN9: =ROUNDUP(H9+K9+N9+Q9+T9+W9+Z9+AC9+AF9+AI9+AL9+AO9+AR9+AU9+AX9+BB9+BE9+BH9+BK9+BM9,0) -> 0 | BO9: =$BO$1 -> 0.47 | BP9: =ROUNDUP(BN9*BO9,0) -> 0 | BQ9: =$BQ$1 -> 0.08 | BR9: =ROUNDUP(BN9*BQ9,0) -> 0 | BS9: =$BS$1 -> 0.05 | BT9: =ROUNDUP(BP9*BS9,0) -> 0 | BV9: =BU9*BN9 -> 0 | BW9: =BN9+BR9 -> 0 | BX9: =BW9*$BX$1 -> 0 | BY9: =BW9*$BY$1 -> 0 | BZ9: =BY9*$BZ$1 -> 0 | CA9: =$CA$1 -> 1.3 | CB9: =$CB$1 -> 1.2 | CC9: =$CC$1 -> 1.17 | CD9: =CC9*CB9*CA9*BX9 -> 0 | CE9: =BZ9 -> 0 | CF9: =BW9*CA9*CB9 -> 0
B10: ADA | C10: 10 | F10: CS - WELD | G10: 0.42 | H10: =ROUNDUP(G10*D10,0) -> 0 | J10: 1.32 | K10: =ROUNDUP(I10*J10,0) -> 0 | M10: 0.68 | N10: =ROUNDUP(M10*L10,0) -> 0 | P10: 0.59 | Q10: =ROUNDUP(P10*O10,0) -> 0 | S10: 1.41 | T10: =ROUNDUP(S10*R10,0) -> 0 | V10: 0.41 | W10: =ROUNDUP(V10*U10,0) -> 0 | Y10: 1.54 | Z10: =ROUNDUP(Y10*X10,0) -> 0 | AB10: 1.04 | AC10: =ROUNDUP(AB10*AA10,0) -> 0 | AF10: =ROUNDUP(AE10*AD10,0) -> 0 | AI10: =ROUNDUP(AH10*AG10,0) -> 0 | AK10: 0.35 | AL10: =ROUNDUP(AK10*AJ10,0) -> 0 | AO10: =ROUNDUP(AN10*AM10,0) -> 0 | AR10: =ROUNDUP(AQ10*AP10,0) -> 0 | AU10: =ROUNDUP(AT10*AS10,0) -> 0 | AV10: =AA10 -> 0 | AW10: 2.57 | AX10: =ROUNDUP(AW10*AV10,0) -> 0 | AY10: =BC10+BF10 -> 0 | AZ10: 0.345 | BA10: =AZ10*C10 -> 3.45 | BB10: =ROUNDUP(BA10*AY10,0) -> 0 | BC10: =ROUNDUP(D10/20,0) -> 0 | BD10: 4.37 | BE10: =ROUNDUP(BC10*BD10,0) -> 0 | BF10: =(I10*2)+(L10*2)+(O10*1)+(R10*3)+(U10*2)+(AA10*1)+(AD10*1)+(AG10*2)+(AJ10*1)+(AM10*2)+(AP10*2)+(AS10*2) -> 0 | BG10: 4.37 | BH10: =ROUNDUP(BF10*BG10,0) -> 0 | BI10: =H10+K10+N10+Q10+T10+W10+Z10+AC10+AF10+AI10+AL10+AO10+AR10+AU10+AX10+BB10+BE10+BH10 -> 0 | BK10: =ROUNDUP((BC10+BF10)*BJ10,0) -> 0 | BM10: =ROUNDUP((BC10+BF10)*BL10,0) -> 0 | BN10: =ROUNDUP(H10+K10+N10+Q10+T10+W10+Z10+AC10+AF10+AI10+AL10+AO10+AR10+AU10+AX10+BB10+BE10+BH10+BK10+BM10,0) -> 0 | BO10: =$BO$1 -> 0.47 | BP10: =ROUNDUP(BN10*BO10,0) -> 0 | BQ10: =$BQ$1 -> 0.08 | BR10: =ROUNDUP(BN10*BQ10,0) -> 0 | BS10: =$BS$1 -> 0.05 | BT10: =ROUNDUP(BP10*BS10,0) -> 0 | BV10: =BU10*BN10 -> 0 | BW10: =BN10+BR10 -> 0 | BX10: =BW10*$BX$1 -> 0 | BY10: =BW10*$BY$1 -> 0 | BZ10: =BY10*$BZ$1 -> 0 | CA10: =$CA$1 -> 1.3 | CB10: =$CB$1 -> 1.2 | CC10: =$CC$1 -> 1.17 | CD10: =CC10*CB10*CA10*BX10 -> 0 | CE10: =BZ10 -> 0 | CF10: =BW10*CA10*CB10 -> 0
B11: ADA | C11: 12 | F11: CS - WELD | G11: 0.48 | H11: =ROUNDUP(G11*D11,0) -> 0 | J11: 1.92 | K11: =ROUNDUP(I11*J11,0) -> 0 | M11: 0.98 | N11: =ROUNDUP(M11*L11,0) -> 0 | P11: 0.93 | Q11: =ROUNDUP(P11*O11,0) -> 0 | S11: 2.25 | T11: =ROUNDUP(S11*R11,0) -> 0 | V11: 0.54 | W11: =ROUNDUP(V11*U11,0) -> 0 | Y11: 2.26 | Z11: =ROUNDUP(Y11*X11,0) -> 0 | AB11: 1.54 | AC11: =ROUNDUP(AB11*AA11,0) -> 0 | AF11: =ROUNDUP(AE11*AD11,0) -> 0 | AI11: =ROUNDUP(AH11*AG11,0) -> 0 | AK11: 0.48 | AL11: =ROUNDUP(AK11*AJ11,0) -> 0 | AO11: =ROUNDUP(AN11*AM11,0) -> 0 | AR11: =ROUNDUP(AQ11*AP11,0) -> 0 | AU11: =ROUNDUP(AT11*AS11,0) -> 0 | AV11: =AA11 -> 0 | AW11: 2.54 | AX11: =ROUNDUP(AW11*AV11,0) -> 0 | AY11: =BC11+BF11 -> 0 | AZ11: 0.345 | BA11: =AZ11*C11 -> 4.14 | BB11: =ROUNDUP(BA11*AY11,0) -> 0 | BC11: =ROUNDUP(D11/20,0) -> 0 | BD11: 5.24 | BE11: =ROUNDUP(BC11*BD11,0) -> 0 | BF11: =(I11*2)+(L11*2)+(O11*1)+(R11*3)+(U11*2)+(AA11*1)+(AD11*1)+(AG11*2)+(AJ11*1)+(AM11*2)+(AP11*2)+(AS11*2) -> 0 | BG11: 5.24 | BH11: =ROUNDUP(BF11*BG11,0) -> 0 | BI11: =H11+K11+N11+Q11+T11+W11+Z11+AC11+AF11+AI11+AL11+AO11+AR11+AU11+AX11+BB11+BE11+BH11 -> 0 | BK11: =ROUNDUP((BC11+BF11)*BJ11,0) -> 0 | BM11: =ROUNDUP((BC11+BF11)*BL11,0) -> 0 | BN11: =ROUNDUP(H11+K11+N11+Q11+T11+W11+Z11+AC11+AF11+AI11+AL11+AO11+AR11+AU11+AX11+BB11+BE11+BH11+BK11+BM11,0) -> 0 | BO11: =$BO$1 -> 0.47 | BP11: =ROUNDUP(BN11*BO11,0) -> 0 | BQ11: =$BQ$1 -> 0.08 | BR11: =ROUNDUP(BN11*BQ11,0) -> 0 | BS11: =$BS$1 -> 0.05 | BT11: =ROUNDUP(BP11*BS11,0) -> 0 | BV11: =BU11*BN11 -> 0 | BW11: =BN11+BR11 -> 0 | BX11: =BW11*$BX$1 -> 0 | BY11: =BW11*$BY$1 -> 0 | BZ11: =BY11*$BZ$1 -> 0 | CA11: =$CA$1 -> 1.3 | CB11: =$CB$1 -> 1.2 | CC11: =$CC$1 -> 1.17 | CD11: =CC11*CB11*CA11*BX11 -> 0 | CE11: =BZ11 -> 0 | CF11: =BW11*CA11*CB11 -> 0
B12: ADA | C12: 14 | F12: CS - WELD | G12: 0.49 | H12: =ROUNDUP(G12*D12,0) -> 0 | J12: 2.48 | K12: =ROUNDUP(I12*J12,0) -> 0 | M12: 1.28 | N12: =ROUNDUP(M12*L12,0) -> 0 | P12: 1.04 | Q12: =ROUNDUP(P12*O12,0) -> 0 | S12: 3.44 | T12: =ROUNDUP(S12*R12,0) -> 0 | V12: 0.93 | W12: =ROUNDUP(V12*U12,0) -> 0 | Y12: 3.88 | Z12: =ROUNDUP(Y12*X12,0) -> 0 | AB12: 2.06 | AC12: =ROUNDUP(AB12*AA12,0) -> 0 | AF12: =ROUNDUP(AE12*AD12,0) -> 0 | AI12: =ROUNDUP(AH12*AG12,0) -> 0 | AK12: 0.57 | AL12: =ROUNDUP(AK12*AJ12,0) -> 0 | AO12: =ROUNDUP(AN12*AM12,0) -> 0 | AR12: =ROUNDUP(AQ12*AP12,0) -> 0 | AU12: =ROUNDUP(AT12*AS12,0) -> 0 | AV12: =AA12 -> 0 | AW12: 3.39 | AX12: =ROUNDUP(AW12*AV12,0) -> 0 | AY12: =BC12+BF12 -> 0 | AZ12: 0.345 | BA12: =AZ12*C12 -> 4.83 | BB12: =ROUNDUP(BA12*AY12,0) -> 0 | BC12: =ROUNDUP(D12/20,0) -> 0 | BD12: 6.12 | BE12: =ROUNDUP(BC12*BD12,0) -> 0 | BF12: =(I12*2)+(L12*2)+(O12*1)+(R12*3)+(U12*2)+(AA12*1)+(AD12*1)+(AG12*2)+(AJ12*1)+(AM12*2)+(AP12*2)+(AS12*2) -> 0 | BG12: 6.12 | BH12: =ROUNDUP(BF12*BG12,0) -> 0 | BI12: =H12+K12+N12+Q12+T12+W12+Z12+AC12+AF12+AI12+AL12+AO12+AR12+AU12+AX12+BB12+BE12+BH12 -> 0 | BK12: =ROUNDUP((BC12+BF12)*BJ12,0) -> 0 | BM12: =ROUNDUP((BC12+BF12)*BL12,0) -> 0 | BN12: =ROUNDUP(H12+K12+N12+Q12+T12+W12+Z12+AC12+AF12+AI12+AL12+AO12+AR12+AU12+AX12+BB12+BE12+BH12+BK12+BM12,0) -> 0 | BO12: =$BO$1 -> 0.47 | BP12: =ROUNDUP(BN12*BO12,0) -> 0 | BQ12: =$BQ$1 -> 0.08 | BR12: =ROUNDUP(BN12*BQ12,0) -> 0 | BS12: =$BS$1 -> 0.05 | BT12: =ROUNDUP(BP12*BS12,0) -> 0 | BV12: =BU12*BN12 -> 0 | BW12: =BN12+BR12 -> 0 | BX12: =BW12*$BX$1 -> 0 | BY12: =BW12*$BY$1 -> 0 | BZ12: =BY12*$BZ$1 -> 0 | CA12: =$CA$1 -> 1.3 | CB12: =$CB$1 -> 1.2 | CC12: =$CC$1 -> 1.17 | CD12: =CC12*CB12*CA12*BX12 -> 0 | CE12: =BZ12 -> 0 | CF12: =BW12*CA12*CB12 -> 0
B13: ADA | C13: 16 | F13: CS - WELD | G13: 0.51 | H13: =ROUNDUP(G13*D13,0) -> 0 | J13: 3.27 | K13: =ROUNDUP(I13*J13,0) -> 0 | M13: 1.7 | N13: =ROUNDUP(M13*L13,0) -> 0 | P13: 1.17 | Q13: =ROUNDUP(P13*O13,0) -> 0 | S13: 3.68 | T13: =ROUNDUP(S13*R13,0) -> 0 | V13: 1.14 | W13: =ROUNDUP(V13*U13,0) -> 0 | Y13: 4.77 | Z13: =ROUNDUP(Y13*X13,0) -> 0 | AB13: 2.66 | AC13: =ROUNDUP(AB13*AA13,0) -> 0 | AF13: =ROUNDUP(AE13*AD13,0) -> 0 | AI13: =ROUNDUP(AH13*AG13,0) -> 0 | AK13: 0.72 | AL13: =ROUNDUP(AK13*AJ13,0) -> 0 | AO13: =ROUNDUP(AN13*AM13,0) -> 0 | AR13: =ROUNDUP(AQ13*AP13,0) -> 0 | AU13: =ROUNDUP(AT13*AS13,0) -> 0 | AV13: =AA13 -> 0 | AW13: 3.87 | AX13: =ROUNDUP(AW13*AV13,0) -> 0 | AY13: =BC13+BF13 -> 0 | AZ13: 0.345 | BA13: =AZ13*C13 -> 5.52 | BB13: =ROUNDUP(BA13*AY13,0) -> 0 | BC13: =ROUNDUP(D13/20,0) -> 0 | BD13: 6.99 | BE13: =ROUNDUP(BC13*BD13,0) -> 0 | BF13: =(I13*2)+(L13*2)+(O13*1)+(R13*3)+(U13*2)+(AA13*1)+(AD13*1)+(AG13*2)+(AJ13*1)+(AM13*2)+(AP13*2)+(AS13*2) -> 0 | BG13: 6.99 | BH13: =ROUNDUP(BF13*BG13,0) -> 0 | BI13: =H13+K13+N13+Q13+T13+W13+Z13+AC13+AF13+AI13+AL13+AO13+AR13+AU13+AX13+BB13+BE13+BH13 -> 0 | BK13: =ROUNDUP((BC13+BF13)*BJ13,0) -> 0 | BM13: =ROUNDUP((BC13+BF13)*BL13,0) -> 0 | BN13: =ROUNDUP(H13+K13+N13+Q13+T13+W13+Z13+AC13+AF13+AI13+AL13+AO13+AR13+AU13+AX13+BB13+BE13+BH13+BK13+BM13,0) -> 0 | BO13: =$BO$1 -> 0.47 | BP13: =ROUNDUP(BN13*BO13,0) -> 0 | BQ13: =$BQ$1 -> 0.08 | BR13: =ROUNDUP(BN13*BQ13,0) -> 0 | BS13: =$BS$1 -> 0.05 | BT13: =ROUNDUP(BP13*BS13,0) -> 0 | BV13: =BU13*BN13 -> 0 | BW13: =BN13+BR13 -> 0 | BX13: =BW13*$BX$1 -> 0 | BY13: =BW13*$BY$1 -> 0 | BZ13: =BY13*$BZ$1 -> 0 | CA13: =$CA$1 -> 1.3 | CB13: =$CB$1 -> 1.2 | CC13: =$CC$1 -> 1.17 | CD13: =CC13*CB13*CA13*BX13 -> 0 | CE13: =BZ13 -> 0 | CF13: =BW13*CA13*CB13 -> 0
B14: ADA | C14: 18 | F14: CS - WELD | G14: 0.52 | H14: =ROUNDUP(G14*D14,0) -> 0 | J14: 3.93 | K14: =ROUNDUP(I14*J14,0) -> 0 | M14: 2.15 | N14: =ROUNDUP(M14*L14,0) -> 0 | P14: 1.5 | Q14: =ROUNDUP(P14*O14,0) -> 0 | S14: 4.34 | T14: =ROUNDUP(S14*R14,0) -> 0 | V14: 1.37 | W14: =ROUNDUP(V14*U14,0) -> 0 | Y14: 5.41 | Z14: =ROUNDUP(Y14*X14,0) -> 0 | AB14: 3.25 | AC14: =ROUNDUP(AB14*AA14,0) -> 0 | AF14: =ROUNDUP(AE14*AD14,0) -> 0 | AI14: =ROUNDUP(AH14*AG14,0) -> 0 | AK14: 0.9 | AL14: =ROUNDUP(AK14*AJ14,0) -> 0 | AO14: =ROUNDUP(AN14*AM14,0) -> 0 | AR14: =ROUNDUP(AQ14*AP14,0) -> 0 | AU14: =ROUNDUP(AT14*AS14,0) -> 0 | AV14: =AA14 -> 0 | AW14: 4.35 | AX14: =ROUNDUP(AW14*AV14,0) -> 0 | AY14: =BC14+BF14 -> 0 | AZ14: 0.345 | BA14: =AZ14*C14 -> 6.21 | BB14: =ROUNDUP(BA14*AY14,0) -> 0 | BC14: =ROUNDUP(D14/20,0) -> 0 | BD14: 7.86 | BE14: =ROUNDUP(BC14*BD14,0) -> 0 | BF14: =(I14*2)+(L14*2)+(O14*1)+(R14*3)+(U14*2)+(AA14*1)+(AD14*1)+(AG14*2)+(AJ14*1)+(AM14*2)+(AP14*2)+(AS14*2) -> 0 | BG14: 7.86 | BH14: =ROUNDUP(BF14*BG14,0) -> 0 | BI14: =H14+K14+N14+Q14+T14+W14+Z14+AC14+AF14+AI14+AL14+AO14+AR14+AU14+AX14+BB14+BE14+BH14 -> 0 | BK14: =ROUNDUP((BC14+BF14)*BJ14,0) -> 0 | BM14: =ROUNDUP((BC14+BF14)*BL14,0) -> 0 | BN14: =ROUNDUP(H14+K14+N14+Q14+T14+W14+Z14+AC14+AF14+AI14+AL14+AO14+AR14+AU14+AX14+BB14+BE14+BH14+BK14+BM14,0) -> 0 | BO14: =$BO$1 -> 0.47 | BP14: =ROUNDUP(BN14*BO14,0) -> 0 | BQ14: =$BQ$1 -> 0.08 | BR14: =ROUNDUP(BN14*BQ14,0) -> 0 | BS14: =$BS$1 -> 0.05 | BT14: =ROUNDUP(BP14*BS14,0) -> 0 | BV14: =BU14*BN14 -> 0 | BW14: =BN14+BR14 -> 0 | BX14: =BW14*$BX$1 -> 0 | BY14: =BW14*$BY$1 -> 0 | BZ14: =BY14*$BZ$1 -> 0 | CA14: =$CA$1 -> 1.3 | CB14: =$CB$1 -> 1.2 | CC14: =$CC$1 -> 1.17 | CD14: =CC14*CB14*CA14*BX14 -> 0 | CE14: =BZ14 -> 0 | CF14: =BW14*CA14*CB14 -> 0
B15: ADA | C15: 20 | F15: CS - WELD | G15: 0.53 | H15: =ROUNDUP(G15*D15,0) -> 0 | J15: 4.32 | K15: =ROUNDUP(I15*J15,0) -> 0 | M15: 2.67 | N15: =ROUNDUP(M15*L15,0) -> 0 | P15: 1.82 | Q15: =ROUNDUP(P15*O15,0) -> 0 | S15: 5.47 | T15: =ROUNDUP(S15*R15,0) -> 0 | V15: 2.01 | W15: =ROUNDUP(V15*U15,0) -> 0 | Y15: 6.4 | Z15: =ROUNDUP(Y15*X15,0) -> 0 | AB15: 3.99 | AC15: =ROUNDUP(AB15*AA15,0) -> 0 | AF15: =ROUNDUP(AE15*AD15,0) -> 0 | AI15: =ROUNDUP(AH15*AG15,0) -> 0 | AK15: 1.11 | AL15: =ROUNDUP(AK15*AJ15,0) -> 0 | AO15: =ROUNDUP(AN15*AM15,0) -> 0 | AR15: =ROUNDUP(AQ15*AP15,0) -> 0 | AU15: =ROUNDUP(AT15*AS15,0) -> 0 | AV15: =AA15 -> 0 | AW15: 5.44 | AX15: =ROUNDUP(AW15*AV15,0) -> 0 | AY15: =BC15+BF15 -> 0 | AZ15: 0.345 | BA15: =AZ15*C15 -> 6.9 | BB15: =ROUNDUP(BA15*AY15,0) -> 0 | BC15: =ROUNDUP(D15/20,0) -> 0 | BD15: 8.74 | BE15: =ROUNDUP(BC15*BD15,0) -> 0 | BF15: =(I15*2)+(L15*2)+(O15*1)+(R15*3)+(U15*2)+(AA15*1)+(AD15*1)+(AG15*2)+(AJ15*1)+(AM15*2)+(AP15*2)+(AS15*2) -> 0 | BG15: 8.74 | BH15: =ROUNDUP(BF15*BG15,0) -> 0 | BI15: =H15+K15+N15+Q15+T15+W15+Z15+AC15+AF15+AI15+AL15+AO15+AR15+AU15+AX15+BB15+BE15+BH15 -> 0 | BK15: =ROUNDUP((BC15+BF15)*BJ15,0) -> 0 | BM15: =ROUNDUP((BC15+BF15)*BL15,0) -> 0 | BN15: =ROUNDUP(H15+K15+N15+Q15+T15+W15+Z15+AC15+AF15+AI15+AL15+AO15+AR15+AU15+AX15+BB15+BE15+BH15+BK15+BM15,0) -> 0 | BO15: =$BO$1 -> 0.47 | BP15: =ROUNDUP(BN15*BO15,0) -> 0 | BQ15: =$BQ$1 -> 0.08 | BR15: =ROUNDUP(BN15*BQ15,0) -> 0 | BS15: =$BS$1 -> 0.05 | BT15: =ROUNDUP(BP15*BS15,0) -> 0 | BV15: =BU15*BN15 -> 0 | BW15: =BN15+BR15 -> 0 | BX15: =BW15*$BX$1 -> 0 | BY15: =BW15*$BY$1 -> 0 | BZ15: =BY15*$BZ$1 -> 0 | CA15: =$CA$1 -> 1.3 | CB15: =$CB$1 -> 1.2 | CC15: =$CC$1 -> 1.17 | CD15: =CC15*CB15*CA15*BX15 -> 0 | CE15: =BZ15 -> 0 | CF15: =BW15*CA15*CB15 -> 0
B16: ADA | C16: 24 | F16: CS - WELD | G16: 0.55 | H16: =ROUNDUP(G16*D16,0) -> 0 | J16: 5.31 | K16: =ROUNDUP(I16*J16,0) -> 0 | M16: 3.65 | N16: =ROUNDUP(M16*L16,0) -> 0 | P16: 3.35 | Q16: =ROUNDUP(P16*O16,0) -> 0 | S16: 7.19 | T16: =ROUNDUP(S16*R16,0) -> 0 | V16: 2.42 | W16: =ROUNDUP(V16*U16,0) -> 0 | Y16: 9.05 | Z16: =ROUNDUP(Y16*X16,0) -> 0 | AB16: 4.93 | AC16: =ROUNDUP(AB16*AA16,0) -> 0 | AF16: =ROUNDUP(AE16*AD16,0) -> 0 | AI16: =ROUNDUP(AH16*AG16,0) -> 0 | AK16: 1.58 | AL16: =ROUNDUP(AK16*AJ16,0) -> 0 | AO16: =ROUNDUP(AN16*AM16,0) -> 0 | AR16: =ROUNDUP(AQ16*AP16,0) -> 0 | AU16: =ROUNDUP(AT16*AS16,0) -> 0 | AV16: =AA16 -> 0 | AW16: 6.16 | AX16: =ROUNDUP(AW16*AV16,0) -> 0 | AY16: =BC16+BF16 -> 0 | AZ16: 0.345 | BA16: =AZ16*C16 -> 8.28 | BB16: =ROUNDUP(BA16*AY16,0) -> 0 | BC16: =ROUNDUP(D16/20,0) -> 0 | BD16: 10.48 | BE16: =ROUNDUP(BC16*BD16,0) -> 0 | BF16: =(I16*2)+(L16*2)+(O16*1)+(R16*3)+(U16*2)+(AA16*1)+(AD16*1)+(AG16*2)+(AJ16*1)+(AM16*2)+(AP16*2)+(AS16*2) -> 0 | BG16: 10.48 | BH16: =ROUNDUP(BF16*BG16,0) -> 0 | BI16: =H16+K16+N16+Q16+T16+W16+Z16+AC16+AF16+AI16+AL16+AO16+AR16+AU16+AX16+BB16+BE16+BH16 -> 0 | BK16: =ROUNDUP((BC16+BF16)*BJ16,0) -> 0 | BM16: =ROUNDUP((BC16+BF16)*BL16,0) -> 0 | BN16: =ROUNDUP(H16+K16+N16+Q16+T16+W16+Z16+AC16+AF16+AI16+AL16+AO16+AR16+AU16+AX16+BB16+BE16+BH16+BK16+BM16,0) -> 0 | BO16: =$BO$1 -> 0.47 | BP16: =ROUNDUP(BN16*BO16,0) -> 0 | BQ16: =$BQ$1 -> 0.08 | BR16: =ROUNDUP(BN16*BQ16,0) -> 0 | BS16: =$BS$1 -> 0.05 | BT16: =ROUNDUP(BP16*BS16,0) -> 0 | BV16: =BU16*BN16 -> 0 | BW16: =BN16+BR16 -> 0 | BX16: =BW16*$BX$1 -> 0 | BY16: =BW16*$BY$1 -> 0 | BZ16: =BY16*$BZ$1 -> 0 | CA16: =$CA$1 -> 1.3 | CB16: =$CB$1 -> 1.2 | CC16: =$CC$1 -> 1.17 | CD16: =CC16*CB16*CA16*BX16 -> 0 | CE16: =BZ16 -> 0 | CF16: =BW16*CA16*CB16 -> 0
B17: ADA | C17: 30 | F17: CS - WELD | G17: 0.59 | H17: =ROUNDUP(G17*D17,0) -> 0 | J17: 6.98 | K17: =ROUNDUP(I17*J17,0) -> 0 | M17: 4.57 | N17: =ROUNDUP(M17*L17,0) -> 0 | P17: 4.98 | Q17: =ROUNDUP(P17*O17,0) -> 0 | S17: 9.09 | T17: =ROUNDUP(S17*R17,0) -> 0 | V17: 3.6 | W17: =ROUNDUP(V17*U17,0) -> 0 | Y17: 10.15 | Z17: =ROUNDUP(Y17*X17,0) -> 0 | AB17: 4.15 | AC17: =ROUNDUP(AB17*AA17,0) -> 0 | AF17: =ROUNDUP(AE17*AD17,0) -> 0 | AI17: =ROUNDUP(AH17*AG17,0) -> 0 | AK17: 2.1 | AL17: =ROUNDUP(AK17*AJ17,0) -> 0 | AO17: =ROUNDUP(AN17*AM17,0) -> 0 | AR17: =ROUNDUP(AQ17*AP17,0) -> 0 | AU17: =ROUNDUP(AT17*AS17,0) -> 0 | AV17: =AA17 -> 0 | AW17: 7.71 | AX17: =ROUNDUP(AW17*AV17,0) -> 0 | AY17: =BC17+BF17 -> 0 | AZ17: 0.345 | BA17: =AZ17*C17 -> 10.35 | BB17: =ROUNDUP(BA17*AY17,0) -> 0 | BC17: =ROUNDUP(D17/20,0) -> 0 | BD17: 13.11 | BE17: =ROUNDUP(BC17*BD17,0) -> 0 | BF17: =(I17*2)+(L17*2)+(O17*1)+(R17*3)+(U17*2)+(AA17*1)+(AD17*1)+(AG17*2)+(AJ17*1)+(AM17*2)+(AP17*2)+(AS17*2) -> 0 | BG17: 13.11 | BH17: =ROUNDUP(BF17*BG17,0) -> 0 | BI17: =H17+K17+N17+Q17+T17+W17+Z17+AC17+AF17+AI17+AL17+AO17+AR17+AU17+AX17+BB17+BE17+BH17 -> 0 | BK17: =ROUNDUP((BC17+BF17)*BJ17,0) -> 0 | BM17: =ROUNDUP((BC17+BF17)*BL17,0) -> 0 | BN17: =ROUNDUP(H17+K17+N17+Q17+T17+W17+Z17+AC17+AF17+AI17+AL17+AO17+AR17+AU17+AX17+BB17+BE17+BH17+BK17+BM17,0) -> 0 | BO17: =$BO$1 -> 0.47 | BP17: =ROUNDUP(BN17*BO17,0) -> 0 | BQ17: =$BQ$1 -> 0.08 | BR17: =ROUNDUP(BN17*BQ17,0) -> 0 | BS17: =$BS$1 -> 0.05 | BT17: =ROUNDUP(BP17*BS17,0) -> 0 | BV17: =BU17*BN17 -> 0 | BW17: =BN17+BR17 -> 0 | BX17: =BW17*$BX$1 -> 0 | BY17: =BW17*$BY$1 -> 0 | BZ17: =BY17*$BZ$1 -> 0 | CA17: =$CA$1 -> 1.3 | CB17: =$CB$1 -> 1.2 | CC17: =$CC$1 -> 1.17 | CD17: =CC17*CB17*CA17*BX17 -> 0 | CE17: =BZ17 -> 0 | CF17: =BW17*CA17*CB17 -> 0
B18: ADA | C18: 36 | F18: CS - WELD | G18: 0.63 | H18: =ROUNDUP(G18*D18,0) -> 0 | J18: 8.99 | K18: =ROUNDUP(I18*J18,0) -> 0 | M18: 5.64 | N18: =ROUNDUP(M18*L18,0) -> 0 | P18: 8.09 | Q18: =ROUNDUP(P18*O18,0) -> 0 | S18: 9.82 | T18: =ROUNDUP(S18*R18,0) -> 0 | V18: 4.03 | W18: =ROUNDUP(V18*U18,0) -> 0 | Y18: 11.93 | Z18: =ROUNDUP(Y18*X18,0) -> 0 | AB18: 5.13 | AC18: =ROUNDUP(AB18*AA18,0) -> 0 | AF18: =ROUNDUP(AE18*AD18,0) -> 0 | AI18: =ROUNDUP(AH18*AG18,0) -> 0 | AK18: 2.52 | AL18: =ROUNDUP(AK18*AJ18,0) -> 0 | AO18: =ROUNDUP(AN18*AM18,0) -> 0 | AR18: =ROUNDUP(AQ18*AP18,0) -> 0 | AU18: =ROUNDUP(AT18*AS18,0) -> 0 | AV18: =AA18 -> 0 | AW18: 9.25 | AX18: =ROUNDUP(AW18*AV18,0) -> 0 | AY18: =BC18+BF18 -> 0 | AZ18: 0.345 | BA18: =AZ18*C18 -> 12.42 | BB18: =ROUNDUP(BA18*AY18,0) -> 0 | BC18: =ROUNDUP(D18/20,0) -> 0 | BD18: 15.73 | BE18: =ROUNDUP(BC18*BD18,0) -> 0 | BF18: =(I18*2)+(L18*2)+(O18*1)+(R18*3)+(U18*2)+(AA18*1)+(AD18*1)+(AG18*2)+(AJ18*1)+(AM18*2)+(AP18*2)+(AS18*2) -> 0 | BG18: 15.73 | BH18: =ROUNDUP(BF18*BG18,0) -> 0 | BI18: =H18+K18+N18+Q18+T18+W18+Z18+AC18+AF18+AI18+AL18+AO18+AR18+AU18+AX18+BB18+BE18+BH18 -> 0 | BK18: =ROUNDUP((BC18+BF18)*BJ18,0) -> 0 | BM18: =ROUNDUP((BC18+BF18)*BL18,0) -> 0 | BN18: =ROUNDUP(H18+K18+N18+Q18+T18+W18+Z18+AC18+AF18+AI18+AL18+AO18+AR18+AU18+AX18+BB18+BE18+BH18+BK18+BM18,0) -> 0 | BO18: =$BO$1 -> 0.47 | BP18: =ROUNDUP(BN18*BO18,0) -> 0 | BQ18: =$BQ$1 -> 0.08 | BR18: =ROUNDUP(BN18*BQ18,0) -> 0 | BS18: =$BS$1 -> 0.05 | BT18: =ROUNDUP(BP18*BS18,0) -> 0 | BV18: =BU18*BN18 -> 0 | BW18: =BN18+BR18 -> 0 | BX18: =BW18*$BX$1 -> 0 | BY18: =BW18*$BY$1 -> 0 | BZ18: =BY18*$BZ$1 -> 0 | CA18: =$CA$1 -> 1.3 | CB18: =$CB$1 -> 1.2 | CC18: =$CC$1 -> 1.17 | CD18: =CC18*CB18*CA18*BX18 -> 0 | CE18: =BZ18 -> 0 | CF18: =BW18*CA18*CB18 -> 0
B19: ADA | C19: 42 | F19: CS - WELD | G19: 0.66 | H19: =ROUNDUP(G19*D19,0) -> 0 | J19: 5.56 | K19: =ROUNDUP(I19*J19,0) -> 0 | M19: 6.9 | N19: =ROUNDUP(M19*L19,0) -> 0 | P19: 10.07 | Q19: =ROUNDUP(P19*O19,0) -> 0 | S19: 11.75 | T19: =ROUNDUP(S19*R19,0) -> 0 | V19: 4.35 | W19: =ROUNDUP(V19*U19,0) -> 0 | Y19: 13.87 | Z19: =ROUNDUP(Y19*X19,0) -> 0 | AB19: 6.42 | AC19: =ROUNDUP(AB19*AA19,0) -> 0 | AF19: =ROUNDUP(AE19*AD19,0) -> 0 | AI19: =ROUNDUP(AH19*AG19,0) -> 0 | AL19: =ROUNDUP(AK19*AJ19,0) -> 0 | AO19: =ROUNDUP(AN19*AM19,0) -> 0 | AR19: =ROUNDUP(AQ19*AP19,0) -> 0 | AU19: =ROUNDUP(AT19*AS19,0) -> 0 | AV19: =AA19 -> 0 | AW19: 10.79 | AX19: =ROUNDUP(AW19*AV19,0) -> 0 | AY19: =BC19+BF19 -> 0 | AZ19: 0.345 | BA19: =AZ19*C19 -> 14.49 | BB19: =ROUNDUP(BA19*AY19,0) -> 0 | BC19: =ROUNDUP(D19/20,0) -> 0 | BD19: 18.35 | BE19: =ROUNDUP(BC19*BD19,0) -> 0 | BF19: =(I19*2)+(L19*2)+(O19*1)+(R19*3)+(U19*2)+(AA19*1)+(AD19*1)+(AG19*2)+(AJ19*1)+(AM19*2)+(AP19*2)+(AS19*2) -> 0 | BG19: 18.35 | BH19: =ROUNDUP(BF19*BG19,0) -> 0 | BI19: =H19+K19+N19+Q19+T19+W19+Z19+AC19+AF19+AI19+AL19+AO19+AR19+AU19+AX19+BB19+BE19+BH19 -> 0 | BK19: =ROUNDUP((BC19+BF19)*BJ19,0) -> 0 | BM19: =ROUNDUP((BC19+BF19)*BL19,0) -> 0 | BN19: =ROUNDUP(H19+K19+N19+Q19+T19+W19+Z19+AC19+AF19+AI19+AL19+AO19+AR19+AU19+AX19+BB19+BE19+BH19+BK19+BM19,0) -> 0 | BO19: =$BO$1 -> 0.47 | BP19: =ROUNDUP(BN19*BO19,0) -> 0 | BQ19: =$BQ$1 -> 0.08 | BR19: =ROUNDUP(BN19*BQ19,0) -> 0 | BS19: =$BS$1 -> 0.05 | BT19: =ROUNDUP(BP19*BS19,0) -> 0 | BV19: =BU19*BN19 -> 0 | BW19: =BN19+BR19 -> 0 | BX19: =BW19*$BX$1 -> 0 | BY19: =BW19*$BY$1 -> 0 | BZ19: =BY19*$BZ$1 -> 0 | CA19: =$CA$1 -> 1.3 | CB19: =$CB$1 -> 1.2 | CC19: =$CC$1 -> 1.17 | CD19: =CC19*CB19*CA19*BX19 -> 0 | CE19: =BZ19 -> 0 | CF19: =BW19*CA19*CB19 -> 0
B20: ADA | C20: 48 | F20: CS - WELD | G20: 0.7 | H20: =ROUNDUP(G20*D20,0) -> 0 | J20: 10.22 | K20: =ROUNDUP(I20*J20,0) -> 0 | M20: 8.36 | N20: =ROUNDUP(M20*L20,0) -> 0 | P20: 10.07 | Q20: =ROUNDUP(P20*O20,0) -> 0 | S20: 12.22 | T20: =ROUNDUP(S20*R20,0) -> 0 | V20: 4.75 | W20: =ROUNDUP(V20*U20,0) -> 0 | Y20: 15.6 | Z20: =ROUNDUP(Y20*X20,0) -> 0 | AB20: 7.42 | AC20: =ROUNDUP(AB20*AA20,0) -> 0 | AF20: =ROUNDUP(AE20*AD20,0) -> 0 | AI20: =ROUNDUP(AH20*AG20,0) -> 0 | AL20: =ROUNDUP(AK20*AJ20,0) -> 0 | AO20: =ROUNDUP(AN20*AM20,0) -> 0 | AR20: =ROUNDUP(AQ20*AP20,0) -> 0 | AU20: =ROUNDUP(AT20*AS20,0) -> 0 | AV20: =AA20 -> 0 | AW20: 12.33 | AX20: =ROUNDUP(AW20*AV20,0) -> 0 | AY20: =BC20+BF20 -> 0 | AZ20: 0.345 | BA20: =AZ20*C20 -> 16.56 | BB20: =ROUNDUP(BA20*AY20,0) -> 0 | BC20: =ROUNDUP(D20/20,0) -> 0 | BD20: 20.97 | BE20: =ROUNDUP(BC20*BD20,0) -> 0 | BF20: =(I20*2)+(L20*2)+(O20*1)+(R20*3)+(U20*2)+(AA20*1)+(AD20*1)+(AG20*2)+(AJ20*1)+(AM20*2)+(AP20*2)+(AS20*2) -> 0 | BG20: 20.97 | BH20: =ROUNDUP(BF20*BG20,0) -> 0 | BI20: =H20+K20+N20+Q20+T20+W20+Z20+AC20+AF20+AI20+AL20+AO20+AR20+AU20+AX20+BB20+BE20+BH20 -> 0 | BK20: =ROUNDUP((BC20+BF20)*BJ20,0) -> 0 | BM20: =ROUNDUP((BC20+BF20)*BL20,0) -> 0 | BN20: =ROUNDUP(H20+K20+N20+Q20+T20+W20+Z20+AC20+AF20+AI20+AL20+AO20+AR20+AU20+AX20+BB20+BE20+BH20+BK20+BM20,0) -> 0 | BO20: =$BO$1 -> 0.47 | BP20: =ROUNDUP(BN20*BO20,0) -> 0 | BQ20: =$BQ$1 -> 0.08 | BR20: =ROUNDUP(BN20*BQ20,0) -> 0 | BS20: =$BS$1 -> 0.05 | BT20: =ROUNDUP(BP20*BS20,0) -> 0 | BV20: =BU20*BN20 -> 0 | BW20: =BN20+BR20 -> 0 | BX20: =BW20*$BX$1 -> 0 | BY20: =BW20*$BY$1 -> 0 | BZ20: =BY20*$BZ$1 -> 0 | CA20: =$CA$1 -> 1.3 | CB20: =$CB$1 -> 1.2 | CC20: =$CC$1 -> 1.17 | CD20: =CC20*CB20*CA20*BX20 -> 0 | CE20: =BZ20 -> 0 | CF20: =BW20*CA20*CB20 -> 0
B21: ADAV | C21: 2.5 | F21: CS - WELD | G21: 0.16 | H21: =ROUNDUP(G21*D21,0) -> 0 | J21: 0.12 | K21: =ROUNDUP(I21*J21,0) -> 0 | M21: 0.08 | N21: =ROUNDUP(M21*L21,0) -> 0 | P21: 0.11 | Q21: =ROUNDUP(P21*O21,0) -> 0 | S21: 0.17 | T21: =ROUNDUP(S21*R21,0) -> 0 | V21: 0.08 | W21: =ROUNDUP(V21*U21,0) -> 0 | Y21: 0.41 | Z21: =ROUNDUP(Y21*X21,0) -> 0 | AB21: 0.22 | AC21: =ROUNDUP(AB21*AA21,0) -> 0 | AF21: 0 | AI21: 0 | AK21: 0.07 | AL21: =ROUNDUP(AK21*AJ21,0) -> 0 | AO21: 0 | AR21: 0 | AU21: =ROUNDUP(AT21*AS21,0) -> 0 | AV21: =AA21 -> 0 | AW21: 0.71 | AX21: =ROUNDUP(AW21*AV21,0) -> 0 | AY21: =BC21+BF21 -> 0 | AZ21: 0.345 | BA21: =AZ21*C21 -> 0.8625 | BB21: =ROUNDUP(BA21*AY21,0) -> 0 | BC21: =ROUNDUP(D21/20,0) -> 0 | BD21: 1.79 | BE21: =ROUNDUP(BC21*BD21,0) -> 0 | BF21: =(I21*2)+(L21*2)+(O21*1)+(R21*3)+(U21*2)+(AA21*1)+(AD21*1)+(AG21*2)+(AJ21*1)+(AM21*2)+(AP21*2)+(AS21*2) -> 0 | BG21: 1.79 | BH21: =ROUNDUP(BF21*BG21,0) -> 0 | BI21: =H21+K21+N21+Q21+T21+W21+Z21+AC21+AF21+AI21+AL21+AO21+AR21+AU21+AX21+BB21+BE21+BH21 -> 0 | BK21: =ROUNDUP((BC21+BF21)*BJ21,0) -> 0 | BM21: =ROUNDUP((BC21+BF21)*BL21,0) -> 0 | BN21: =ROUNDUP(H21+K21+N21+Q21+T21+W21+Z21+AC21+AF21+AI21+AL21+AO21+AR21+AU21+AX21+BB21+BE21+BH21+BK21+BM21,0) -> 0 | BO21: =$BO$1 -> 0.47 | BP21: =ROUNDUP(BN21*BO21,0) -> 0 | BR21: =ROUNDUP(BN21*BQ21,0) -> 0 | BS21: =$BS$1 -> 0.05 | BT21: =ROUNDUP(BN21*BS21,0) -> 0 | BV21: =BU21*BN21 -> 0 | BW21: =BN21+BR21+BP21+BT21+BV21 -> 0 | BX21: =BW21*$BX$1 -> 0 | BY21: =BW21*$BY$1 -> 0 | BZ21: =BY21*$BZ$1 -> 0 | CA21: =$CA$1 -> 1.3 | CB21: =$CB$1 -> 1.2 | CC21: =$CC$1 -> 1.17 | CD21: =CC21*CB21*CA21*BX21 -> 0 | CE21: =BZ21 -> 0 | CF21: =CE21+CD21 -> 0
B22: ADAV | C22: 3 | F22: CS - WELD | G22: 0.16 | H22: =ROUNDUP(G22*D22,0) -> 0 | J22: 0.12 | K22: =ROUNDUP(I22*J22,0) -> 0 | M22: 0.08 | N22: =ROUNDUP(M22*L22,0) -> 0 | P22: 0.11 | Q22: =ROUNDUP(P22*O22,0) -> 0 | S22: 0.17 | T22: =ROUNDUP(S22*R22,0) -> 0 | V22: 0.08 | W22: =ROUNDUP(V22*U22,0) -> 0 | Y22: 0.41 | Z22: =ROUNDUP(Y22*X22,0) -> 0 | AB22: 0.22 | AC22: =ROUNDUP(AB22*AA22,0) -> 0 | AF22: 0 | AI22: 0 | AK22: 0.07 | AL22: =ROUNDUP(AK22*AJ22,0) -> 0 | AO22: 0 | AR22: 0 | AU22: =ROUNDUP(AT22*AS22,0) -> 0 | AV22: =AA22 -> 0 | AW22: 0.71 | AX22: =ROUNDUP(AW22*AV22,0) -> 0 | AY22: =BC22+BF22 -> 0 | AZ22: 0.345 | BA22: =AZ22*C22 -> 1.035 | BB22: =ROUNDUP(BA22*AY22,0) -> 0 | BC22: =ROUNDUP(D22/20,0) -> 0 | BD22: 1.79 | BE22: =ROUNDUP(BC22*BD22,0) -> 0 | BF22: =(I22*2)+(L22*2)+(O22*1)+(R22*3)+(U22*2)+(AA22*1)+(AD22*1)+(AG22*2)+(AJ22*1)+(AM22*2)+(AP22*2)+(AS22*2) -> 0 | BG22: 1.79 | BH22: =ROUNDUP(BF22*BG22,0) -> 0 | BI22: =H22+K22+N22+Q22+T22+W22+Z22+AC22+AF22+AI22+AL22+AO22+AR22+AU22+AX22+BB22+BE22+BH22 -> 0 | BK22: =ROUNDUP((BC22+BF22)*BJ22,0) -> 0 | BM22: =ROUNDUP((BC22+BF22)*BL22,0) -> 0 | BN22: =ROUNDUP(H22+K22+N22+Q22+T22+W22+Z22+AC22+AF22+AI22+AL22+AO22+AR22+AU22+AX22+BB22+BE22+BH22+BK22+BM22,0) -> 0 | BO22: =$BO$1 -> 0.47 | BP22: =ROUNDUP(BN22*BO22,0) -> 0 | BR22: =ROUNDUP(BN22*BQ22,0) -> 0 | BS22: =$BS$1 -> 0.05 | BT22: =ROUNDUP(BN22*BS22,0) -> 0 | BV22: =BU22*BN22 -> 0 | BW22: =BN22+BR22+BP22+BT22+BV22 -> 0 | BX22: =BW22*$BX$1 -> 0 | BY22: =BW22*$BY$1 -> 0 | BZ22: =BY22*$BZ$1 -> 0 | CA22: =$CA$1 -> 1.3 | CB22: =$CB$1 -> 1.2 | CC22: =$CC$1 -> 1.17 | CD22: =CC22*CB22*CA22*BX22 -> 0 | CE22: =BZ22 -> 0 | CF22: =CE22+CD22 -> 0
B23: ADAV | C23: 4 | F23: CS - WELD | G23: 0.21 | H23: =ROUNDUP(G23*D23,0) -> 0 | J23: 0.18 | K23: =ROUNDUP(I23*J23,0) -> 0 | M23: 0.11 | N23: =ROUNDUP(M23*L23,0) -> 0 | P23: 0.14 | Q23: =ROUNDUP(P23*O23,0) -> 0 | S23: 0.24 | T23: =ROUNDUP(S23*R23,0) -> 0 | V23: 0.1 | W23: =ROUNDUP(V23*U23,0) -> 0 | Y23: 0.55 | Z23: =ROUNDUP(Y23*X23,0) -> 0 | AB23: 0.29 | AC23: =ROUNDUP(AB23*AA23,0) -> 0 | AF23: 0 | AI23: 0 | AK23: 0.08 | AL23: =ROUNDUP(AK23*AJ23,0) -> 0 | AO23: 0 | AR23: 0 | AU23: =ROUNDUP(AT23*AS23,0) -> 0 | AV23: =AA23 -> 0 | AW23: 1.49 | AX23: =ROUNDUP(AW23*AV23,0) -> 0 | AY23: =BC23+BF23 -> 0 | AZ23: 0.345 | BA23: =AZ23*C23 -> 1.38 | BB23: =ROUNDUP(BA23*AY23,0) -> 0 | BC23: =ROUNDUP(D23/20,0) -> 0 | BD23: 2.21 | BE23: =ROUNDUP(BC23*BD23,0) -> 0 | BF23: =(I23*2)+(L23*2)+(O23*1)+(R23*3)+(U23*2)+(AA23*1)+(AD23*1)+(AG23*2)+(AJ23*1)+(AM23*2)+(AP23*2)+(AS23*2) -> 0 | BG23: 2.21 | BH23: =ROUNDUP(BF23*BG23,0) -> 0 | BI23: =H23+K23+N23+Q23+T23+W23+Z23+AC23+AF23+AI23+AL23+AO23+AR23+AU23+AX23+BB23+BE23+BH23 -> 0 | BK23: =ROUNDUP((BC23+BF23)*BJ23,0) -> 0 | BM23: =ROUNDUP((BC23+BF23)*BL23,0) -> 0 | BN23: =ROUNDUP(H23+K23+N23+Q23+T23+W23+Z23+AC23+AF23+AI23+AL23+AO23+AR23+AU23+AX23+BB23+BE23+BH23+BK23+BM23,0) -> 0 | BO23: =$BO$1 -> 0.47 | BP23: =ROUNDUP(BN23*BO23,0) -> 0 | BR23: =ROUNDUP(BN23*BQ23,0) -> 0 | BS23: =$BS$1 -> 0.05 | BT23: =ROUNDUP(BN23*BS23,0) -> 0 | BV23: =BU23*BN23 -> 0 | BW23: =BN23+BR23+BP23+BT23+BV23 -> 0 | BX23: =BW23*$BX$1 -> 0 | BY23: =BW23*$BY$1 -> 0 | BZ23: =BY23*$BZ$1 -> 0 | CA23: =$CA$1 -> 1.3 | CB23: =$CB$1 -> 1.2 | CC23: =$CC$1 -> 1.17 | CD23: =CC23*CB23*CA23*BX23 -> 0 | CE23: =BZ23 -> 0 | CF23: =CE23+CD23 -> 0
B24: ADAV | C24: 6 | F24: CS - WELD | G24: 0.28 | H24: =ROUNDUP(G24*D24,0) -> 0 | J24: 0.41 | K24: =ROUNDUP(I24*J24,0) -> 0 | M24: 0.23 | N24: =ROUNDUP(M24*L24,0) -> 0 | P24: 0.23 | Q24: =ROUNDUP(P24*O24,0) -> 0 | S24: 0.59 | T24: =ROUNDUP(S24*R24,0) -> 0 | V24: 0.18 | W24: =ROUNDUP(V24*U24,0) -> 0 | Y24: 0.8 | Z24: =ROUNDUP(Y24*X24,0) -> 0 | AB24: 0.44 | AC24: =ROUNDUP(AB24*AA24,0) -> 0 | AF24: 0 | AI24: 0 | AK24: 0.14 | AL24: =ROUNDUP(AK24*AJ24,0) -> 0 | AO24: 0 | AQ24: 5.67 | AR24: =ROUNDUP(AQ24*AP24,0) -> 0 | AU24: =ROUNDUP(AT24*AS24,0) -> 0 | AV24: =AA24 -> 0 | AW24: 1.63 | AX24: =ROUNDUP(AW24*AV24,0) -> 0 | AY24: =BC24+BF24 -> 0 | AZ24: 0.345 | BA24: =AZ24*C24 -> 2.07 | BB24: =ROUNDUP(BA24*AY24,0) -> 0 | BC24: =ROUNDUP(D24/20,0) -> 0 | BD24: 2.8 | BE24: =ROUNDUP(BC24*BD24,0) -> 0 | BF24: =(I24*2)+(L24*2)+(O24*1)+(R24*3)+(U24*2)+(AA24*1)+(AD24*1)+(AG24*2)+(AJ24*1)+(AM24*2)+(AP24*2)+(AS24*2) -> 0 | BG24: 2.8 | BH24: =ROUNDUP(BF24*BG24,0) -> 0 | BI24: =H24+K24+N24+Q24+T24+W24+Z24+AC24+AF24+AI24+AL24+AO24+AR24+AU24+AX24+BB24+BE24+BH24 -> 0 | BK24: =ROUNDUP((BC24+BF24)*BJ24,0) -> 0 | BM24: =ROUNDUP((BC24+BF24)*BL24,0) -> 0 | BN24: =ROUNDUP(H24+K24+N24+Q24+T24+W24+Z24+AC24+AF24+AI24+AL24+AO24+AR24+AU24+AX24+BB24+BE24+BH24+BK24+BM24,0) -> 0 | BO24: =$BO$1 -> 0.47 | BP24: =ROUNDUP(BN24*BO24,0) -> 0 | BR24: =ROUNDUP(BN24*BQ24,0) -> 0 | BS24: =$BS$1 -> 0.05 | BT24: =ROUNDUP(BN24*BS24,0) -> 0 | BV24: =BU24*BN24 -> 0 | BW24: =BN24+BR24+BP24+BT24+BV24 -> 0 | BX24: =BW24*$BX$1 -> 0 | BY24: =BW24*$BY$1 -> 0 | BZ24: =BY24*$BZ$1 -> 0 | CA24: =$CA$1 -> 1.3 | CB24: =$CB$1 -> 1.2 | CC24: =$CC$1 -> 1.17 | CD24: =CC24*CB24*CA24*BX24 -> 0 | CE24: =BZ24 -> 0 | CF24: =CE24+CD24 -> 0
B25: ADAV | C25: 8 | F25: CS - WELD | G25: 0.34 | H25: =ROUNDUP(G25*D25,0) -> 0 | J25: 0.77 | K25: =ROUNDUP(I25*J25,0) -> 0 | M25: 0.41 | N25: =ROUNDUP(M25*L25,0) -> 0 | P25: 0.39 | Q25: =ROUNDUP(P25*O25,0) -> 0 | S25: 0.96 | T25: =ROUNDUP(S25*R25,0) -> 0 | V25: 0.26 | W25: =ROUNDUP(V25*U25,0) -> 0 | Y25: 1.19 | Z25: =ROUNDUP(Y25*X25,0) -> 0 | AB25: 0.72 | AC25: =ROUNDUP(AB25*AA25,0) -> 0 | AF25: 0 | AI25: 0 | AK25: 0.21 | AL25: =ROUNDUP(AK25*AJ25,0) -> 0 | AO25: 0 | AR25: 0 | AU25: =ROUNDUP(AT25*AS25,0) -> 0 | AV25: =AA25 -> 0 | AW25: 1.58 | AX25: =ROUNDUP(AW25*AV25,0) -> 0 | AY25: =BC25+BF25 -> 0 | AZ25: 0.345 | BA25: =AZ25*C25 -> 2.76 | BB25: =ROUNDUP(BA25*AY25,0) -> 0 | BC25: =ROUNDUP(D25/20,0) -> 0 | BD25: 3.5 | BE25: =ROUNDUP(BC25*BD25,0) -> 0 | BF25: =(I25*2)+(L25*2)+(O25*1)+(R25*3)+(U25*2)+(AA25*1)+(AD25*1)+(AG25*2)+(AJ25*1)+(AM25*2)+(AP25*2)+(AS25*2) -> 0 | BG25: 3.5 | BH25: =ROUNDUP(BF25*BG25,0) -> 0 | BI25: =H25+K25+N25+Q25+T25+W25+Z25+AC25+AF25+AI25+AL25+AO25+AR25+AU25+AX25+BB25+BE25+BH25 -> 0 | BK25: =ROUNDUP((BC25+BF25)*BJ25,0) -> 0 | BM25: =ROUNDUP((BC25+BF25)*BL25,0) -> 0 | BN25: =ROUNDUP(H25+K25+N25+Q25+T25+W25+Z25+AC25+AF25+AI25+AL25+AO25+AR25+AU25+AX25+BB25+BE25+BH25+BK25+BM25,0) -> 0 | BO25: =$BO$1 -> 0.47 | BP25: =ROUNDUP(BN25*BO25,0) -> 0 | BQ25: =$BQ$1 -> 0.08 | BR25: =ROUNDUP(BN25*BQ25,0) -> 0 | BS25: =$BS$1 -> 0.05 | BT25: =ROUNDUP(BN25*BS25,0) -> 0 | BV25: =BU25*BN25 -> 0 | BW25: =BN25+BR25+BP25+BT25+BV25 -> 0 | BX25: =BW25*$BX$1 -> 0 | BY25: =BW25*$BY$1 -> 0 | BZ25: =BY25*$BZ$1 -> 0 | CA25: =$CA$1 -> 1.3 | CB25: =$CB$1 -> 1.2 | CC25: =$CC$1 -> 1.17 | CD25: =CC25*CB25*CA25*BX25 -> 0 | CE25: =BZ25 -> 0 | CF25: =CE25+CD25 -> 0
B26: ADB | C26: 1 | F26: CS - WELD | G26: 0.07 | H26: =ROUNDUP(G26*D26,0) -> 0 | J26: 0.06 | K26: =ROUNDUP(I26*J26,0) -> 0 | M26: 0.06 | N26: =ROUNDUP(M26*L26,0) -> 0 | Q26: =ROUNDUP(P26*O26,0) -> 0 | S26: 0.06 | T26: =ROUNDUP(S26*R26,0) -> 0 | V26: 0.05 | W26: =ROUNDUP(V26*U26,0) -> 0 | Y26: 0.1 | Z26: =ROUNDUP(Y26*X26,0) -> 0 | AB26: 0.08 | AC26: =ROUNDUP(AB26*AA26,0) -> 0 | AF26: =ROUNDUP(AE26*AD26,0) -> 0 | AI26: =ROUNDUP(AH26*AG26,0) -> 0 | AK26: 0.05 | AL26: =ROUNDUP(AK26*AJ26,0) -> 0 | AN26: 0.05 | AO26: =ROUNDUP(AN26*AM26,0) -> 0 | AQ26: 0.06 | AR26: =ROUNDUP(AQ26*AP26,0) -> 0 | AU26: =ROUNDUP(AT26*AS26,0) -> 0 | AV26: =AA26 -> 0 | AW26: 0.44 | AX26: =ROUNDUP(AW26*AV26,0) -> 0 | AY26: =BC26+BF26 -> 0 | AZ26: 0.345 | BA26: =AZ26*C26 -> 0.345 | BB26: =ROUNDUP(BA26*AY26,0) -> 0 | BC26: =ROUNDUP(D26/20,0) -> 0 | BD26: 0.37 | BE26: =ROUNDUP(BC26*BD26,0) -> 0 | BF26: =(I26*2)+(L26*2)+(O26*1)+(R26*3)+(U26*2)+(AA26*1)+(AD26*1)+(AG26*2)+(AJ26*1)+(AM26*2)+(AP26*2)+(AS26*2) -> 0 | BG26: 0.37 | BH26: =ROUNDUP(BF26*BG26,0) -> 0 | BI26: =H26+K26+N26+Q26+T26+W26+Z26+AC26+AF26+AI26+AL26+AO26+AR26+AU26+AX26+BB26+BE26+BH26 -> 0 | BK26: =ROUNDUP((BC26+BF26)*BJ26,0) -> 0 | BM26: =ROUNDUP((BC26+BF26)*BL26,0) -> 0 | BN26: =ROUNDUP(H26+K26+N26+Q26+T26+W26+Z26+AC26+AF26+AI26+AL26+AO26+AR26+AU26+AX26+BB26+BE26+BH26+BK26+BM26,0) -> 0 | BO26: =$BO$1 -> 0.47 | BP26: =ROUNDUP(BN26*BO26,0) -> 0 | BR26: =ROUNDUP(BN26*BQ26,0) -> 0 | BS26: =$BS$1 -> 0.05 | BT26: =ROUNDUP(BN26*BS26,0) -> 0 | BV26: =BU26*BN26 -> 0 | BW26: =BN26+BR26+BP26+BT26+BV26 -> 0 | BX26: =BW26*$BX$1 -> 0 | BY26: =BW26*$BY$1 -> 0 | BZ26: =BY26*$BZ$1 -> 0 | CA26: =$CA$1 -> 1.3 | CB26: =$CB$1 -> 1.2 | CC26: =$CC$1 -> 1.17 | CD26: =CC26*CB26*CA26*BX26 -> 0 | CE26: =BZ26 -> 0 | CF26: =CE26+CD26 -> 0
B27: ADB | C27: 1.25 | F27: CS - THRD | G27: 0.08 | H27: =ROUNDUP(G27*D27,0) -> 0 | J27: 0.07 | K27: =ROUNDUP(I27*J27,0) -> 0 | M27: 0.07 | N27: =ROUNDUP(M27*L27,0) -> 0 | Q27: =ROUNDUP(P27*O27,0) -> 0 | S27: 0.08 | T27: =ROUNDUP(S27*R27,0) -> 0 | V27: 0.06 | W27: =ROUNDUP(V27*U27,0) -> 0 | Y27: 0.12 | Z27: =ROUNDUP(Y27*X27,0) -> 0 | AB27: 0.09 | AC27: =ROUNDUP(AB27*AA27,0) -> 0 | AF27: =ROUNDUP(AE27*AD27,0) -> 0 | AI27: =ROUNDUP(AH27*AG27,0) -> 0 | AK27: 0.06 | AL27: =ROUNDUP(AK27*AJ27,0) -> 0 | AN27: 0.06 | AO27: =ROUNDUP(AN27*AM27,0) -> 0 | AR27: =ROUNDUP(AQ27*AP27,0) -> 0 | AU27: =ROUNDUP(AT27*AS27,0) -> 0 | AV27: =AA27 -> 0 | AW27: 0.69 | AX27: =ROUNDUP(AW27*AV27,0) -> 0 | AY27: =BC27+BF27 -> 0 | AZ27: 0.345 | BA27: =AZ27*C27 -> 0.43125 | BB27: =ROUNDUP(BA27*AY27,0) -> 0 | BC27: =ROUNDUP(D27/20,0) -> 0 | BD27: 0.42 | BE27: =ROUNDUP(BC27*BD27,0) -> 0 | BF27: =(I27*2)+(L27*2)+(O27*1)+(R27*3)+(U27*2)+(AA27*1)+(AD27*1)+(AG27*2)+(AJ27*1)+(AM27*2)+(AP27*2)+(AS27*2) -> 0 | BG27: 0.42 | BH27: =ROUNDUP(BF27*BG27,0) -> 0 | BI27: =H27+K27+N27+Q27+T27+W27+Z27+AC27+AF27+AI27+AL27+AO27+AR27+AU27+AX27+BB27+BE27+BH27 -> 0 | BK27: =ROUNDUP((BC27+BF27)*BJ27,0) -> 0 | BM27: =ROUNDUP((BC27+BF27)*BL27,0) -> 0 | BN27: =ROUNDUP(H27+K27+N27+Q27+T27+W27+Z27+AC27+AF27+AI27+AL27+AO27+AR27+AU27+AX27+BB27+BE27+BH27+BK27+BM27,0) -> 0 | BO27: =$BO$1 -> 0.47 | BP27: =ROUNDUP(BN27*BO27,0) -> 0 | BR27: =ROUNDUP(BN27*BQ27,0) -> 0 | BS27: =$BS$1 -> 0.05 | BT27: =ROUNDUP(BN27*BS27,0) -> 0 | BV27: =BU27*BN27 -> 0 | BW27: =BN27+BR27+BP27+BT27+BV27 -> 0 | BX27: =BW27*$BX$1 -> 0 | BY27: =BW27*$BY$1 -> 0 | BZ27: =BY27*$BZ$1 -> 0 | CA27: =$CA$1 -> 1.3 | CB27: =$CB$1 -> 1.2 | CC27: =$CC$1 -> 1.17 | CD27: =CC27*CB27*CA27*BX27 -> 0 | CE27: =BZ27 -> 0 | CF27: =CE27+CD27 -> 0
B28: ADB | C28: 1.5 | F28: CS - THRD | G28: 0.09 | H28: =ROUNDUP(G28*D28,0) -> 0 | J28: 0.08 | K28: =ROUNDUP(I28*J28,0) -> 0 | M28: 0.07 | N28: =ROUNDUP(M28*L28,0) -> 0 | Q28: =ROUNDUP(P28*O28,0) -> 0 | S28: 0.08 | T28: =ROUNDUP(S28*R28,0) -> 0 | V28: 0.06 | W28: =ROUNDUP(V28*U28,0) -> 0 | Y28: 0.16 | Z28: =ROUNDUP(Y28*X28,0) -> 0 | AB28: 0.1 | AC28: =ROUNDUP(AB28*AA28,0) -> 0 | AF28: =ROUNDUP(AE28*AD28,0) -> 0 | AI28: =ROUNDUP(AH28*AG28,0) -> 0 | AK28: 0.06 | AL28: =ROUNDUP(AK28*AJ28,0) -> 0 | AN28: 0.06 | AO28: =ROUNDUP(AN28*AM28,0) -> 0 | AR28: =ROUNDUP(AQ28*AP28,0) -> 0 | AU28: =ROUNDUP(AT28*AS28,0) -> 0 | AV28: =AA28 -> 0 | AW28: 0.69 | AX28: =ROUNDUP(AW28*AV28,0) -> 0 | AY28: =BC28+BF28 -> 0 | AZ28: 0.345 | BA28: =AZ28*C28 -> 0.5175 | BB28: =ROUNDUP(BA28*AY28,0) -> 0 | BC28: =ROUNDUP(D28/20,0) -> 0 | BD28: 0.46 | BE28: =ROUNDUP(BC28*BD28,0) -> 0 | BF28: =(I28*2)+(L28*2)+(O28*1)+(R28*3)+(U28*2)+(AA28*1)+(AD28*1)+(AG28*2)+(AJ28*1)+(AM28*2)+(AP28*2)+(AS28*2) -> 0 | BG28: 0.46 | BH28: =ROUNDUP(BF28*BG28,0) -> 0 | BI28: =H28+K28+N28+Q28+T28+W28+Z28+AC28+AF28+AI28+AL28+AO28+AR28+AU28+AX28+BB28+BE28+BH28 -> 0 | BK28: =ROUNDUP((BC28+BF28)*BJ28,0) -> 0 | BM28: =ROUNDUP((BC28+BF28)*BL28,0) -> 0 | BN28: =ROUNDUP(H28+K28+N28+Q28+T28+W28+Z28+AC28+AF28+AI28+AL28+AO28+AR28+AU28+AX28+BB28+BE28+BH28+BK28+BM28,0) -> 0 | BO28: =$BO$1 -> 0.47 | BP28: =ROUNDUP(BN28*BO28,0) -> 0 | BR28: =ROUNDUP(BN28*BQ28,0) -> 0 | BS28: =$BS$1 -> 0.05 | BT28: =ROUNDUP(BN28*BS28,0) -> 0 | BV28: =BU28*BN28 -> 0 | BW28: =BN28+BR28+BP28+BT28+BV28 -> 0 | BX28: =BW28*$BX$1 -> 0 | BY28: =BW28*$BY$1 -> 0 | BZ28: =BY28*$BZ$1 -> 0 | CA28: =$CA$1 -> 1.3 | CB28: =$CB$1 -> 1.2 | CC28: =$CC$1 -> 1.17 | CD28: =CC28*CB28*CA28*BX28 -> 0 | CE28: =BZ28 -> 0 | CF28: =CE28+CD28 -> 0
B29: ADB | C29: 2 | F29: CS - THRD | G29: 0.1 | H29: =ROUNDUP(G29*D29,0) -> 0 | J29: 0.09 | K29: =ROUNDUP(I29*J29,0) -> 0 | M29: 0.09 | N29: =ROUNDUP(M29*L29,0) -> 0 | Q29: =ROUNDUP(P29*O29,0) -> 0 | S29: 0.11 | T29: =ROUNDUP(S29*R29,0) -> 0 | V29: 0.08 | W29: =ROUNDUP(V29*U29,0) -> 0 | Y29: 0.28 | Z29: =ROUNDUP(Y29*X29,0) -> 0 | AB29: 0.13 | AC29: =ROUNDUP(AB29*AA29,0) -> 0 | AF29: =ROUNDUP(AE29*AD29,0) -> 0 | AI29: =ROUNDUP(AH29*AG29,0) -> 0 | AK29: 0.07 | AL29: =ROUNDUP(AK29*AJ29,0) -> 0 | AN29: 0.08 | AO29: =ROUNDUP(AN29*AM29,0) -> 0 | AR29: =ROUNDUP(AQ29*AP29,0) -> 0 | AU29: =ROUNDUP(AT29*AS29,0) -> 0 | AV29: =AA29 -> 0 | AW29: 0.74 | AX29: =ROUNDUP(AW29*AV29,0) -> 0 | AY29: =BC29+BF29 -> 0 | AZ29: 0.345 | BA29: =AZ29*C29 -> 0.69 | BB29: =ROUNDUP(BA29*AY29,0) -> 0 | BC29: =ROUNDUP(D29/20,0) -> 0 | BD29: 0.56 | BE29: =ROUNDUP(BC29*BD29,0) -> 0 | BF29: =(I29*2)+(L29*2)+(O29*1)+(R29*3)+(U29*2)+(AA29*1)+(AD29*1)+(AG29*2)+(AJ29*1)+(AM29*2)+(AP29*2)+(AS29*2) -> 0 | BG29: 0.56 | BH29: =ROUNDUP(BF29*BG29,0) -> 0 | BI29: =H29+K29+N29+Q29+T29+W29+Z29+AC29+AF29+AI29+AL29+AO29+AR29+AU29+AX29+BB29+BE29+BH29 -> 0 | BK29: =ROUNDUP((BC29+BF29)*BJ29,0) -> 0 | BM29: =ROUNDUP((BC29+BF29)*BL29,0) -> 0 | BN29: =ROUNDUP(H29+K29+N29+Q29+T29+W29+Z29+AC29+AF29+AI29+AL29+AO29+AR29+AU29+AX29+BB29+BE29+BH29+BK29+BM29,0) -> 0 | BO29: =$BO$1 -> 0.47 | BP29: =ROUNDUP(BN29*BO29,0) -> 0 | BR29: =ROUNDUP(BN29*BQ29,0) -> 0 | BS29: =$BS$1 -> 0.05 | BT29: =ROUNDUP(BN29*BS29,0) -> 0 | BV29: =BU29*BN29 -> 0 | BW29: =BN29+BR29+BP29+BT29+BV29 -> 0 | BX29: =BW29*$BX$1 -> 0 | BY29: =BW29*$BY$1 -> 0 | BZ29: =BY29*$BZ$1 -> 0 | CA29: =$CA$1 -> 1.3 | CB29: =$CB$1 -> 1.2 | CC29: =$CC$1 -> 1.17 | CD29: =CC29*CB29*CA29*BX29 -> 0 | CE29: =BZ29 -> 0 | CF29: =CE29+CD29 -> 0
B30: JEAB | C30: 0.5 | F30: SS - WELD | G30: 0.06 | H30: =ROUNDUP(G30*D30,0) -> 0 | J30: 0.05 | K30: =ROUNDUP(I30*J30,0) -> 0 | M30: 0.05 | N30: =ROUNDUP(M30*L30,0) -> 0 | P30: 0.05 | Q30: =ROUNDUP(P30*O30,0) -> 0 | S30: 0.05 | T30: =ROUNDUP(S30*R30,0) -> 0 | V30: 0.05 | W30: =ROUNDUP(V30*U30,0) -> 0 | Y30: 0.12 | Z30: =ROUNDUP(Y30*X30,0) -> 0 | AB30: 0.06 | AC30: =ROUNDUP(AB30*AA30,0) -> 0 | AE30: 0.05 | AF30: =ROUNDUP(AE30*AD30,0) -> 0 | AI30: =ROUNDUP(AH30*AG30,0) -> 0 | AK30: 0.05 | AL30: =ROUNDUP(AK30*AJ30,0) -> 0 | AO30: =ROUNDUP(AN30*AM30,0) -> 0 | AR30: =ROUNDUP(AQ30*AP30,0) -> 0 | AU30: =ROUNDUP(AT30*AS30,0) -> 0 | AV30: =AA30 -> 0 | AW30: 0.47 | AX30: =ROUNDUP(AW30*AV30,0) -> 0 | AY30: =BC30+BF30 -> 0 | AZ30: 0.345 | BA30: =AZ30*C30 -> 0.1725 | BB30: =ROUNDUP(BA30*AY30,0) -> 0 | BC30: =ROUNDUP(D30/20,0) -> 0 | BD30: 0.59 | BE30: =ROUNDUP(BC30*BD30,0) -> 0 | BF30: =(I30*2)+(L30*2)+(O30*1)+(R30*3)+(U30*2)+(AA30*1)+(AD30*1)+(AG30*2)+(AJ30*1)+(AM30*2)+(AP30*2)+(AS30*2) -> 0 | BG30: 0.59 | BH30: =ROUNDUP(BF30*BG30,0) -> 0 | BI30: =H30+K30+N30+Q30+T30+W30+Z30+AC30+AF30+AI30+AL30+AO30+AR30+AU30+AX30+BB30+BE30+BH30 -> 0 | BJ30: 0.21 | BK30: =ROUNDUP((BC30+BF30)*BJ30,0) -> 0 | BL30: 0.21 | BM30: =ROUNDUP((BC30+BF30)*BL30,0) -> 0 | BN30: =ROUNDUP(H30+K30+N30+Q30+T30+W30+Z30+AC30+AF30+AI30+AL30+AO30+AR30+AU30+AX30+BB30+BE30+BH30+BK30+BM30,0) -> 0 | BO30: =$BO$1 -> 0.47 | BP30: =ROUNDUP(BN30*BO30,0) -> 0 | BR30: =ROUNDUP(BN30*BQ30,0) -> 0 | BS30: =$BS$1 -> 0.05 | BT30: =ROUNDUP(BN30*BS30,0) -> 0 | BU30: =$BU$1 -> 0.71 | BV30: =BU30*BN30 -> 0 | BW30: =BN30+BR30+BP30+BT30+BV30 -> 0 | BX30: =BW30*$BX$1 -> 0 | BY30: =BW30*$BY$1 -> 0 | BZ30: =BY30*$BZ$1 -> 0 | CA30: =$CA$1 -> 1.3 | CB30: =$CB$1 -> 1.2 | CC30: =$CC$1 -> 1.17 | CD30: =CC30*CB30*CA30*BX30 -> 0 | CE30: =BZ30 -> 0 | CF30: =CE30+CD30 -> 0
B31: JEAB | C31: 0.75 | F31: SS - WELD | G31: 0.07 | H31: =ROUNDUP(G31*D31,0) -> 0 | J31: 0.05 | K31: =ROUNDUP(I31*J31,0) -> 0 | M31: 0.05 | N31: =ROUNDUP(M31*L31,0) -> 0 | P31: 0.05 | Q31: =ROUNDUP(P31*O31,0) -> 0 | S31: 0.05 | T31: =ROUNDUP(S31*R31,0) -> 0 | V31: 0.05 | W31: =ROUNDUP(V31*U31,0) -> 0 | Y31: 0.17 | Z31: =ROUNDUP(Y31*X31,0) -> 0 | AB31: 0.08 | AC31: =ROUNDUP(AB31*AA31,0) -> 0 | AE31: 0.05 | AF31: =ROUNDUP(AE31*AD31,0) -> 0 | AI31: =ROUNDUP(AH31*AG31,0) -> 0 | AK31: 0.05 | AL31: =ROUNDUP(AK31*AJ31,0) -> 0 | AN31: 0.05 | AO31: =ROUNDUP(AN31*AM31,0) -> 0 | AR31: =ROUNDUP(AQ31*AP31,0) -> 0 | AU31: =ROUNDUP(AT31*AS31,0) -> 0 | AV31: =AA31 -> 0 | AW31: 0.7 | AX31: =ROUNDUP(AW31*AV31,0) -> 0 | AY31: =BC31+BF31 -> 0 | AZ31: 0.345 | BA31: =AZ31*C31 -> 0.25875 | BB31: =ROUNDUP(BA31*AY31,0) -> 0 | BC31: =ROUNDUP(D31/20,0) -> 0 | BD31: 1.18 | BE31: =ROUNDUP(BC31*BD31,0) -> 0 | BF31: =(I31*2)+(L31*2)+(O31*1)+(R31*3)+(U31*2)+(AA31*1)+(AD31*1)+(AG31*2)+(AJ31*1)+(AM31*2)+(AP31*2)+(AS31*2) -> 0 | BG31: 1.18 | BH31: =ROUNDUP(BF31*BG31,0) -> 0 | BI31: =H31+K31+N31+Q31+T31+W31+Z31+AC31+AF31+AI31+AL31+AO31+AR31+AU31+AX31+BB31+BE31+BH31 -> 0 | BJ31: 0.23 | BK31: =ROUNDUP((BC31+BF31)*BJ31,0) -> 0 | BL31: 0.21 | BM31: =ROUNDUP((BC31+BF31)*BL31,0) -> 0 | BN31: =ROUNDUP(H31+K31+N31+Q31+T31+W31+Z31+AC31+AF31+AI31+AL31+AO31+AR31+AU31+AX31+BB31+BE31+BH31+BK31+BM31,0) -> 0 | BO31: =$BO$1 -> 0.47 | BP31: =ROUNDUP(BN31*BO31,0) -> 0 | BR31: =ROUNDUP(BN31*BQ31,0) -> 0 | BS31: =$BS$1 -> 0.05 | BT31: =ROUNDUP(BN31*BS31,0) -> 0 | BU31: =$BU$1 -> 0.71 | BV31: =BU31*BN31 -> 0 | BW31: =BN31+BR31+BP31+BT31+BV31 -> 0 | BX31: =BW31*$BX$1 -> 0 | BY31: =BW31*$BY$1 -> 0 | BZ31: =BY31*$BZ$1 -> 0 | CA31: =$CA$1 -> 1.3 | CB31: =$CB$1 -> 1.2 | CC31: =$CC$1 -> 1.17 | CD31: =CC31*CB31*CA31*BX31 -> 0 | CE31: =BZ31 -> 0 | CF31: =CE31+CD31 -> 0
